Workbook

Sheet 1.설정(통합)
A1: 항목 | B1: 따이 | C1: 린팍 | D1: 추언 | E1: 키우 | F1: 황피선
A2: 기본 정보
A3: 입 사 일 | B3: 46127 | C3: 46119 | D3: 46122 | E3: 46119 | F3: 46119
A4: 사원코드 | B4: 010 | D4: 009 | E4: 008
A5: 부서명 | B5: 생산부 | C5: 생산부 | D5: 생산부 | E5: 생산부 | F5: 건설현장
A6: 성명 | B6: 따이 | C6: 린팍 | D6: 트란 넉 추언 | E6: 다오 티엔 키우 | F6: 황피선
A7: 직급 | B7: 사원 | C7: 사원 | D7: 사원 | E7: 사원
A8: 예금주
A9: 계좌번호
A10: 기본 시급 | B10: 10320 | C10: 10320 | D10: 10320 | E10: 10320 | F10: 10320
A11: 연장/휴일 가산율 | B11: 1.5 | C11: 1.5 | D11: 1.5 | E11: 1.5 | F11: 1.5
A12: 휴일연장 가산율 | B12: 2 | C12: 2 | D12: 2 | E12: 2 | F12: 2
A13: 심야 가산율 | B13: 0.5 | C13: 0.5 | D13: 0.5 | E13: 0.5 | F13: 0.5
A14: 점심시간(시간) | B14: 1 | C14: 1 | D14: 1 | E14: 1 | F14: 1
A15: 변동/고정 수당
A16: 성과금 | B16: 0 | C16: 0 | D16: 0 | E16: 0 | F16: 0
A17: 식대 | B17: 0 | C17: 0 | D17: 0 | E17: 0 | F17: 0
A18: 자가운전보조비 | B18: 0 | C18: 0 | D18: 0 | E18: 0 | F18: 0
A19: 숙소료 | B19: 100000 | C19: 100000 | D19: 100000 | E19: 100000 | F19: 0
A20: 가불금 | B20: 120000 | C20: 120000 | D20: 120000 | E20: 120000 | F20: 0

Sheet 2.공휴일리스트
A1: 날짜 | B1: 공휴일명
A2: 46023 | B2: 신정
A3: 46082 | B3: 삼일절
A4: 46143 | B4: 근로자의날
A5: 46147 | B5: 어린이날
A6: 46179 | B6: 현충일
A7: 46249 | B7: 광복절
A8: 46298 | B8: 개천절
A9: 46304 | B9: 한글날
A10: 46381 | B10: 성탄절
A11: 46388 | B11: 신정
A12: 46447 | B12: 삼일절
A13: 46508 | B13: 근로자의날
... A46: 47842 | B46: 성탄절

Sheet 3.출퇴근기록부(통합)
A1: ▶ 연도/월 입력 | E1: 연도: | F1: 26 | G1: 월: | H1: 4
D2: 따이 | K2: 린팍 | R2: 추언 | Y2: 키우 | AF2: 황피선
A3: 일 | B3: 요일 | C3: 휴일 | D3: 출근 | E3: 퇴근 | F3: 기본 | G3: 연장 | H3: 휴일 | I3: 휴일연장 | J3: 심야 | K3: 출근 | L3: 퇴근 | M3: 기본 | N3: 연장 | O3: 휴일 | P3: 휴일연장 | Q3: 심야 | R3: 출근 | S3: 퇴근 | T3: 기본 | U3: 연장 | V3: 휴일 | W3: 휴일연장 | X3: 심야 | Y3: 출근 | Z3: 퇴근 | AA3: 기본 | AB3: 연장 | AC3: 휴일 | AD3: 휴일연장 | AE3: 심야 | AF3: 출근 | AG3: 퇴근 | AH3: 기본 | AI3: 연장 | AJ3: 휴일 | AK3: 휴일연장 | AL3: 심야
A4: =IFERROR(IF(DAY(DATE(2000+$F$1,$H$1+1,0))<1,"",DATE(2000+$F$1,$H$1,1)),"") -> 46113 | B4: =IF(A4="","",CHOOSE(WEEKDAY(A4),"일","월","화","수","목","금","토")) -> 수 | C4: =IF(A4="","",IF(OR(WEEKDAY(A4,2)>5,COUNTIF('2.공휴일리스트'!$A$2:$A$1000,A4)>0),"휴일","평일")) -> 평일 | F4: =IFERROR(IF(OR(D4="",E4=""),"",IF($C4="평일",MIN(8,MAX(0,(E4-D4)*24-'1.설정(통합)'!$B$14)),0)),"") | G4: =IFERROR(IF(OR(D4="",E4="",$C4="휴일"),"",IF((E4-D4)*24-'1.설정(통합)'!$B$14>8,(E4-D4)*24-'1.설정(통합)'!$B$14-8,0)),"") | H4: =IFERROR(IF(OR(D4="",E4="",$C4="평일"),"",MIN(8,MAX(0,(E4-D4)*24-'1.설정(통합)'!$B$14))),"") | I4: =IFERROR(IF(OR(D4="",E4="",$C4="평일"),"",IF((E4-D4)*24-'1.설정(통합)'!$B$14>8,(E4-D4)*24-'1.설정(통합)'!$B$14-8,0)),"") | J4: =IFERROR(IF(OR(D4="",E4=""),"",MAX(0,(MIN(E4,TIME(24,0,0)+TIME(6,0,0))-MAX(D4,TIME(22,0,0)))*24)+MAX(0,(MIN(E4,TIME(6,0,0))-MAX(D4,TIME(0,0,0)))*24)),"") | M4: =IFERROR(IF(OR(K4="",L4=""),"",IF($C4="평일",MIN(8,MAX(0,(L4-K4)*24-'1.설정(통합)'!$C$14)),0)),"") | N4: =IFERROR(IF(OR(K4="",L4="",$C4="휴일"),"",IF((L4-K4)*24-'1.설정(통합)'!$C$14>8,(L4-K4)*24-'1.설정(통합)'!$C$14-8,0)),"") | O4: =IFERROR(IF(OR(K4="",L4="",$C4="평일"),"",MIN(8,MAX(0,(L4-K4)*24-'1.설정(통합)'!$C$14))),"") | P4: =IFERROR(IF(OR(K4="",L4="",$C4="평일"),"",IF((L4-K4)*24-'1.설정(통합)'!$C$14>8,(L4-K4)*24-'1.설정(통합)'!$C$14-8,0)),"") | Q4: =IFERROR(IF(OR(K4="",L4=""),"",MAX(0,(MIN(L4,TIME(24,0,0)+TIME(6,0,0))-MAX(K4,TIME(22,0,0)))*24)+MAX(0,(MIN(L4,TIME(6,0,0))-MAX(K4,TIME(0,0,0)))*24)),"") | T4: =IFERROR(IF(OR(R4="",S4=""),"",IF($C4="평일",MIN(8,MAX(0,(S4-R4)*24-'1.설정(통합)'!$D$14)),0)),"") | U4: =IFERROR(IF(OR(R4="",S4="",$C4="휴일"),"",IF((S4-R4)*24-'1.설정(통합)'!$D$14>8,(S4-R4)*24-'1.설정(통합)'!$D$14-8,0)),"") | V4: =IFERROR(IF(OR(R4="",S4="",$C4="평일"),"",MIN(8,MAX(0,(S4-R4)*24-'1.설정(통합)'!$D$14))),"") | W4: =IFERROR(IF(OR(R4="",S4="",$C4="평일"),"",IF((S4-R4)*24-'1.설정(통합)'!$D$14>8,(S4-R4)*24-'1.설정(통합)'!$D$14-8,0)),"") | X4: =IFERROR(IF(OR(R4="",S4=""),"",MAX(0,(MIN(S4,TIME(24,0,0)+TIME(6,0,0))-MAX(R4,TIME(22,0,0)))*24)+MAX(0,(MIN(S4,TIME(6,0,0))-MAX(R4,TIME(0,0,0)))*24)),"") | AA4: =IFERROR(IF(OR(Y4="",Z4=""),"",IF($C4="평일",MIN(8,MAX(0,(Z4-Y4)*24-'1.설정(통합)'!$E$14)),0)),"") | AB4: =IFERROR(IF(OR(Y4="",Z4="",$C4="휴일"),"",IF((Z4-Y4)*24-'1.설정(통합)'!$E$14>8,(Z4-Y4)*24-'1.설정(통합)'!$E$14-8,0)),"") | AC4: =IFERROR(IF(OR(Y4="",Z4="",$C4="평일"),"",MIN(8,MAX(0,(Z4-Y4)*24-'1.설정(통합)'!$E$14))),"") | AD4: =IFERROR(IF(OR(Y4="",Z4="",$C4="평일"),"",IF((Z4-Y4)*24-'1.설정(통합)'!$E$14>8,(Z4-Y4)*24-'1.설정(통합)'!$E$14-8,0)),"") | AE4: =IFERROR(IF(OR(Y4="",Z4=""),"",MAX(0,(MIN(Z4,TIME(24,0,0)+TIME(6,0,0))-MAX(Y4,TIME(22,0,0)))*24)+MAX(0,(MIN(Z4,TIME(6,0,0))-MAX(Y4,TIME(0,0,0)))*24)),"") | AH4: =IFERROR(IF(OR(AF4="",AG4=""),"",IF($C4="평일",MIN(8,MAX(0,(AG4-AF4)*24-'1.설정(통합)'!$F$14)),0)),"") | AI4: =IFERROR(IF(OR(AF4="",AG4="",$C4="휴일"),"",IF((AG4-AF4)*24-'1.설정(통합)'!$F$14>8,(AG4-AF4)*24-'1.설정(통합)'!$F$14-8,0)),"") | AJ4: =IFERROR(IF(OR(AF4="",AG4="",$C4="평일"),"",MIN(8,MAX(0,(AG4-AF4)*24-'1.설정(통합)'!$F$14))),"") | AK4: =IFERROR(IF(OR(AF4="",AG4="",$C4="평일"),"",IF((AG4-AF4)*24-'1.설정(통합)'!$F$14>8,(AG4-AF4)*24-'1.설정(통합)'!$F$14-8,0)),"") | AL4: =IFERROR(IF(OR(AF4="",AG4=""),"",MAX(0,(MIN(AG4,TIME(24,0,0)+TIME(6,0,0))-MAX(AF4,TIME(22,0,0)))*24)+MAX(0,(MIN(AG4,TIME(6,0,0))-MAX(AF4,TIME(0,0,0)))*24)),"")
A5: =IFERROR(IF(DAY(DATE(2000+$F$1,$H$1+1,0))<2,"",DATE(2000+$F$1,$H$1,2)),"") -> 46114 | B5: =IF(A5="","",CHOOSE(WEEKDAY(A5),"일","월","화","수","목","금","토")) -> 목 | C5: =IF(A5="","",IF(OR(WEEKDAY(A5,2)>5,COUNTIF('2.공휴일리스트'!$A$2:$A$1000,A5)>0),"휴일","평일")) -> 평일 | F5: =IFERROR(IF(OR(D5="",E5=""),"",IF($C5="평일",MIN(8,MAX(0,(E5-D5)*24-'1.설정(통합)'!$B$14)),0)),"") | G5: =IFERROR(IF(OR(D5="",E5="",$C5="휴일"),"",IF((E5-D5)*24-'1.설정(통합)'!$B$14>8,(E5-D5)*24-'1.설정(통합)'!$B$14-8,0)),"") | H5: =IFERROR(IF(OR(D5="",E5="",$C5="평일"),"",MIN(8,MAX(0,(E5-D5)*24-'1.설정(통합)'!$B$14))),"") | I5: =IFERROR(IF(OR(D5="",E5="",$C5="평일"),"",IF((E5-D5)*24-'1.설정(통합)'!$B$14>8,(E5-D5)*24-'1.설정(통합)'!$B$14-8,0)),"") | J5: =IFERROR(IF(OR(D5="",E5=""),"",MAX(0,(MIN(E5,TIME(24,0,0)+TIME(6,0,0))-MAX(D5,TIME(22,0,0)))*24)+MAX(0,(MIN(E5,TIME(6,0,0))-MAX(D5,TIME(0,0,0)))*24)),"") | M5: =IFERROR(IF(OR(K5="",L5=""),"",IF($C5="평일",MIN(8,MAX(0,(L5-K5)*24-'1.설정(통합)'!$C$14)),0)),"") | N5: =IFERROR(IF(OR(K5="",L5="",$C5="휴일"),"",IF((L5-K5)*24-'1.설정(통합)'!$C$14>8,(L5-K5)*24-'1.설정(통합)'!$C$14-8,0)),"") | O5: =IFERROR(IF(OR(K5="",L5="",$C5="평일"),"",MIN(8,MAX(0,(L5-K5)*24-'1.설정(통합)'!$C$14))),"") | P5: =IFERROR(IF(OR(K5="",L5="",$C5="평일"),"",IF((L5-K5)*24-'1.설정(통합)'!$C$14>8,(L5-K5)*24-'1.설정(통합)'!$C$14-8,0)),"") | Q5: =IFERROR(IF(OR(K5="",L5=""),"",MAX(0,(MIN(L5,TIME(24,0,0)+TIME(6,0,0))-MAX(K5,TIME(22,0,0)))*24)+MAX(0,(MIN(L5,TIME(6,0,0))-MAX(K5,TIME(0,0,0)))*24)),"") | T5: =IFERROR(IF(OR(R5="",S5=""),"",IF($C5="평일",MIN(8,MAX(0,(S5-R5)*24-'1.설정(통합)'!$D$14)),0)),"") | U5: =IFERROR(IF(OR(R5="",S5="",$C5="휴일"),"",IF((S5-R5)*24-'1.설정(통합)'!$D$14>8,(S5-R5)*24-'1.설정(통합)'!$D$14-8,0)),"") | V5: =IFERROR(IF(OR(R5="",S5="",$C5="평일"),"",MIN(8,MAX(0,(S5-R5)*24-'1.설정(통합)'!$D$14))),"") | W5: =IFERROR(IF(OR(R5="",S5="",$C5="평일"),"",IF((S5-R5)*24-'1.설정(통합)'!$D$14>8,(S5-R5)*24-'1.설정(통합)'!$D$14-8,0)),"") | X5: =IFERROR(IF(OR(R5="",S5=""),"",MAX(0,(MIN(S5,TIME(24,0,0)+TIME(6,0,0))-MAX(R5,TIME(22,0,0)))*24)+MAX(0,(MIN(S5,TIME(6,0,0))-MAX(R5,TIME(0,0,0)))*24)),"") | AA5: =IFERROR(IF(OR(Y5="",Z5=""),"",IF($C5="평일",MIN(8,MAX(0,(Z5-Y5)*24-'1.설정(통합)'!$E$14)),0)),"") | AB5: =IFERROR(IF(OR(Y5="",Z5="",$C5="휴일"),"",IF((Z5-Y5)*24-'1.설정(통합)'!$E$14>8,(Z5-Y5)*24-'1.설정(통합)'!$E$14-8,0)),"") | AC5: =IFERROR(IF(OR(Y5="",Z5="",$C5="평일"),"",MIN(8,MAX(0,(Z5-Y5)*24-'1.설정(통합)'!$E$14))),"") | AD5: =IFERROR(IF(OR(Y5="",Z5="",$C5="평일"),"",IF((Z5-Y5)*24-'1.설정(통합)'!$E$14>8,(Z5-Y5)*24-'1.설정(통합)'!$E$14-8,0)),"") | AE5: =IFERROR(IF(OR(Y5="",Z5=""),"",MAX(0,(MIN(Z5,TIME(24,0,0)+TIME(6,0,0))-MAX(Y5,TIME(22,0,0)))*24)+MAX(0,(MIN(Z5,TIME(6,0,0))-MAX(Y5,TIME(0,0,0)))*24)),"") | AH5: =IFERROR(IF(OR(AF5="",AG5=""),"",IF($C5="평일",MIN(8,MAX(0,(AG5-AF5)*24-'1.설정(통합)'!$F$14)),0)),"") | AI5: =IFERROR(IF(OR(AF5="",AG5="",$C5="휴일"),"",IF((AG5-AF5)*24-'1.설정(통합)'!$F$14>8,(AG5-AF5)*24-'1.설정(통합)'!$F$14-8,0)),"") | AJ5: =IFERROR(IF(OR(AF5="",AG5="",$C5="평일"),"",MIN(8,MAX(0,(AG5-AF5)*24-'1.설정(통합)'!$F$14))),"") | AK5: =IFERROR(IF(OR(AF5="",AG5="",$C5="평일"),"",IF((AG5-AF5)*24-'1.설정(통합)'!$F$14>8,(AG5-AF5)*24-'1.설정(통합)'!$F$14-8,0)),"") | AL5: =IFERROR(IF(OR(AF5="",AG5=""),"",MAX(0,(MIN(AG5,TIME(24,0,0)+TIME(6,0,0))-MAX(AF5,TIME(22,0,0)))*24)+MAX(0,(MIN(AG5,TIME(6,0,0))-MAX(AF5,TIME(0,0,0)))*24)),"")
A6: =IFERROR(IF(DAY(DATE(2000+$F$1,$H$1+1,0))<3,"",DATE(2000+$F$1,$H$1,3)),"") -> 46115 | B6: =IF(A6="","",CHOOSE(WEEKDAY(A6),"일","월","화","수","목","금","토")) -> 금 | C6: =IF(A6="","",IF(OR(WEEKDAY(A6,2)>5,COUNTIF('2.공휴일리스트'!$A$2:$A$1000,A6)>0),"휴일","평일")) -> 평일 | F6: =IFERROR(IF(OR(D6="",E6=""),"",IF($C6="평일",MIN(8,MAX(0,(E6-D6)*24-'1.설정(통합)'!$B$14)),0)),"") | G6: =IFERROR(IF(OR(D6="",E6="",$C6="휴일"),"",IF((E6-D6)*24-'1.설정(통합)'!$B$14>8,(E6-D6)*24-'1.설정(통합)'!$B$14-8,0)),"") | H6: =IFERROR(IF(OR(D6="",E6="",$C6="평일"),"",MIN(8,MAX(0,(E6-D6)*24-'1.설정(통합)'!$B$14))),"") | I6: =IFERROR(IF(OR(D6="",E6="",$C6="평일"),"",IF((E6-D6)*24-'1.설정(통합)'!$B$14>8,(E6-D6)*24-'1.설정(통합)'!$B$14-8,0)),"") | J6: =IFERROR(IF(OR(D6="",E6=""),"",MAX(0,(MIN(E6,TIME(24,0,0)+TIME(6,0,0))-MAX(D6,TIME(22,0,0)))*24)+MAX(0,(MIN(E6,TIME(6,0,0))-MAX(D6,TIME(0,0,0)))*24)),"") | M6: =IFERROR(IF(OR(K6="",L6=""),"",IF($C6="평일",MIN(8,MAX(0,(L6-K6)*24-'1.설정(통합)'!$C$14)),0)),"") | N6: =IFERROR(IF(OR(K6="",L6="",$C6="휴일"),"",IF((L6-K6)*24-'1.설정(통합)'!$C$14>8,(L6-K6)*24-'1.설정(통합)'!$C$14-8,0)),"") | O6: =IFERROR(IF(OR(K6="",L6="",$C6="평일"),"",MIN(8,MAX(0,(L6-K6)*24-'1.설정(통합)'!$C$14))),"") | P6: =IFERROR(IF(OR(K6="",L6="",$C6="평일"),"",IF((L6-K6)*24-'1.설정(통합)'!$C$14>8,(L6-K6)*24-'1.설정(통합)'!$C$14-8,0)),"") | Q6: =IFERROR(IF(OR(K6="",L6=""),"",MAX(0,(MIN(L6,TIME(24,0,0)+TIME(6,0,0))-MAX(K6,TIME(22,0,0)))*24)+MAX(0,(MIN(L6,TIME(6,0,0))-MAX(K6,TIME(0,0,0)))*24)),"") | T6: =IFERROR(IF(OR(R6="",S6=""),"",IF($C6="평일",MIN(8,MAX(0,(S6-R6)*24-'1.설정(통합)'!$D$14)),0)),"") | U6: =IFERROR(IF(OR(R6="",S6="",$C6="휴일"),"",IF((S6-R6)*24-'1.설정(통합)'!$D$14>8,(S6-R6)*24-'1.설정(통합)'!$D$14-8,0)),"") | V6: =IFERROR(IF(OR(R6="",S6="",$C6="평일"),"",MIN(8,MAX(0,(S6-R6)*24-'1.설정(통합)'!$D$14))),"") | W6: =IFERROR(IF(OR(R6="",S6="",$C6="평일"),"",IF((S6-R6)*24-'1.설정(통합)'!$D$14>8,(S6-R6)*24-'1.설정(통합)'!$D$14-8,0)),"") | X6: =IFERROR(IF(OR(R6="",S6=""),"",MAX(0,(MIN(S6,TIME(24,0,0)+TIME(6,0,0))-MAX(R6,TIME(22,0,0)))*24)+MAX(0,(MIN(S6,TIME(6,0,0))-MAX(R6,TIME(0,0,0)))*24)),"") | AA6: =IFERROR(IF(OR(Y6="",Z6=""),"",IF($C6="평일",MIN(8,MAX(0,(Z6-Y6)*24-'1.설정(통합)'!$E$14)),0)),"") | AB6: =IFERROR(IF(OR(Y6="",Z6="",$C6="휴일"),"",IF((Z6-Y6)*24-'1.설정(통합)'!$E$14>8,(Z6-Y6)*24-'1.설정(통합)'!$E$14-8,0)),"") | AC6: =IFERROR(IF(OR(Y6="",Z6="",$C6="평일"),"",MIN(8,MAX(0,(Z6-Y6)*24-'1.설정(통합)'!$E$14))),"") | AD6: =IFERROR(IF(OR(Y6="",Z6="",$C6="평일"),"",IF((Z6-Y6)*24-'1.설정(통합)'!$E$14>8,(Z6-Y6)*24-'1.설정(통합)'!$E$14-8,0)),"") | AE6: =IFERROR(IF(OR(Y6="",Z6=""),"",MAX(0,(MIN(Z6,TIME(24,0,0)+TIME(6,0,0))-MAX(Y6,TIME(22,0,0)))*24)+MAX(0,(MIN(Z6,TIME(6,0,0))-MAX(Y6,TIME(0,0,0)))*24)),"") | AH6: =IFERROR(IF(OR(AF6="",AG6=""),"",IF($C6="평일",MIN(8,MAX(0,(AG6-AF6)*24-'1.설정(통합)'!$F$14)),0)),"") | AI6: =IFERROR(IF(OR(AF6="",AG6="",$C6="휴일"),"",IF((AG6-AF6)*24-'1.설정(통합)'!$F$14>8,(AG6-AF6)*24-'1.설정(통합)'!$F$14-8,0)),"") | AJ6: =IFERROR(IF(OR(AF6="",AG6="",$C6="평일"),"",MIN(8,MAX(0,(AG6-AF6)*24-'1.설정(통합)'!$F$14))),"") | AK6: =IFERROR(IF(OR(AF6="",AG6="",$C6="평일"),"",IF((AG6-AF6)*24-'1.설정(통합)'!$F$14>8,(AG6-AF6)*24-'1.설정(통합)'!$F$14-8,0)),"") | AL6: =IFERROR(IF(OR(AF6="",AG6=""),"",MAX(0,(MIN(AG6,TIME(24,0,0)+TIME(6,0,0))-MAX(AF6,TIME(22,0,0)))*24)+MAX(0,(MIN(AG6,TIME(6,0,0))-MAX(AF6,TIME(0,0,0)))*24)),"")
A7: =IFERROR(IF(DAY(DATE(2000+$F$1,$H$1+1,0))<4,"",DATE(2000+$F$1,$H$1,4)),"") -> 46116 | B7: =IF(A7="","",CHOOSE(WEEKDAY(A7),"일","월","화","수","목","금","토")) -> 토 | C7: =IF(A7="","",IF(OR(WEEKDAY(A7,2)>5,COUNTIF('2.공휴일리스트'!$A$2:$A$1000,A7)>0),"휴일","평일")) -> 휴일 | F7: =IFERROR(IF(OR(D7="",E7=""),"",IF($C7="평일",MIN(8,MAX(0,(E7-D7)*24-'1.설정(통합)'!$B$14)),0)),"") | G7: =IFERROR(IF(OR(D7="",E7="",$C7="휴일"),"",IF((E7-D7)*24-'1.설정(통합)'!$B$14>8,(E7-D7)*24-'1.설정(통합)'!$B$14-8,0)),"") | H7: =IFERROR(IF(OR(D7="",E7="",$C7="평일"),"",MIN(8,MAX(0,(E7-D7)*24-'1.설정(통합)'!$B$14))),"") | I7: =IFERROR(IF(OR(D7="",E7="",$C7="평일"),"",IF((E7-D7)*24-'1.설정(통합)'!$B$14>8,(E7-D7)*24-'1.설정(통합)'!$B$14-8,0)),"") | J7: =IFERROR(IF(OR(D7="",E7=""),"",MAX(0,(MIN(E7,TIME(24,0,0)+TIME(6,0,0))-MAX(D7,TIME(22,0,0)))*24)+MAX(0,(MIN(E7,TIME(6,0,0))-MAX(D7,TIME(0,0,0)))*24)),"") | M7: =IFERROR(IF(OR(K7="",L7=""),"",IF($C7="평일",MIN(8,MAX(0,(L7-K7)*24-'1.설정(통합)'!$C$14)),0)),"") | N7: =IFERROR(IF(OR(K7="",L7="",$C7="휴일"),"",IF((L7-K7)*24-'1.설정(통합)'!$C$14>8,(L7-K7)*24-'1.설정(통합)'!$C$14-8,0)),"") | O7: =IFERROR(IF(OR(K7="",L7="",$C7="평일"),"",MIN(8,MAX(0,(L7-K7)*24-'1.설정(통합)'!$C$14))),"") | P7: =IFERROR(IF(OR(K7="",L7="",$C7="평일"),"",IF((L7-K7)*24-'1.설정(통합)'!$C$14>8,(L7-K7)*24-'1.설정(통합)'!$C$14-8,0)),"") | Q7: =IFERROR(IF(OR(K7="",L7=""),"",MAX(0,(MIN(L7,TIME(24,0,0)+TIME(6,0,0))-MAX(K7,TIME(22,0,0)))*24)+MAX(0,(MIN(L7,TIME(6,0,0))-MAX(K7,TIME(0,0,0)))*24)),"") | T7: =IFERROR(IF(OR(R7="",S7=""),"",IF($C7="평일",MIN(8,MAX(0,(S7-R7)*24-'1.설정(통합)'!$D$14)),0)),"") | U7: =IFERROR(IF(OR(R7="",S7="",$C7="휴일"),"",IF((S7-R7)*24-'1.설정(통합)'!$D$14>8,(S7-R7)*24-'1.설정(통합)'!$D$14-8,0)),"") | V7: =IFERROR(IF(OR(R7="",S7="",$C7="평일"),"",MIN(8,MAX(0,(S7-R7)*24-'1.설정(통합)'!$D$14))),"") | W7: =IFERROR(IF(OR(R7="",S7="",$C7="평일"),"",IF((S7-R7)*24-'1.설정(통합)'!$D$14>8,(S7-R7)*24-'1.설정(통합)'!$D$14-8,0)),"") | X7: =IFERROR(IF(OR(R7="",S7=""),"",MAX(0,(MIN(S7,TIME(24,0,0)+TIME(6,0,0))-MAX(R7,TIME(22,0,0)))*24)+MAX(0,(MIN(S7,TIME(6,0,0))-MAX(R7,TIME(0,0,0)))*24)),"") | AA7: =IFERROR(IF(OR(Y7="",Z7=""),"",IF($C7="평일",MIN(8,MAX(0,(Z7-Y7)*24-'1.설정(통합)'!$E$14)),0)),"") | AB7: =IFERROR(IF(OR(Y7="",Z7="",$C7="휴일"),"",IF((Z7-Y7)*24-'1.설정(통합)'!$E$14>8,(Z7-Y7)*24-'1.설정(통합)'!$E$14-8,0)),"") | AC7: =IFERROR(IF(OR(Y7="",Z7="",$C7="평일"),"",MIN(8,MAX(0,(Z7-Y7)*24-'1.설정(통합)'!$E$14))),"") | AD7: =IFERROR(IF(OR(Y7="",Z7="",$C7="평일"),"",IF((Z7-Y7)*24-'1.설정(통합)'!$E$14>8,(Z7-Y7)*24-'1.설정(통합)'!$E$14-8,0)),"") | AE7: =IFERROR(IF(OR(Y7="",Z7=""),"",MAX(0,(MIN(Z7,TIME(24,0,0)+TIME(6,0,0))-MAX(Y7,TIME(22,0,0)))*24)+MAX(0,(MIN(Z7,TIME(6,0,0))-MAX(Y7,TIME(0,0,0)))*24)),"") | AH7: =IFERROR(IF(OR(AF7="",AG7=""),"",IF($C7="평일",MIN(8,MAX(0,(AG7-AF7)*24-'1.설정(통합)'!$F$14)),0)),"") | AI7: =IFERROR(IF(OR(AF7="",AG7="",$C7="휴일"),"",IF((AG7-AF7)*24-'1.설정(통합)'!$F$14>8,(AG7-AF7)*24-'1.설정(통합)'!$F$14-8,0)),"") | AJ7: =IFERROR(IF(OR(AF7="",AG7="",$C7="평일"),"",MIN(8,MAX(0,(AG7-AF7)*24-'1.설정(통합)'!$F$14))),"") | AK7: =IFERROR(IF(OR(AF7="",AG7="",$C7="평일"),"",IF((AG7-AF7)*24-'1.설정(통합)'!$F$14>8,(AG7-AF7)*24-'1.설정(통합)'!$F$14-8,0)),"") | AL7: =IFERROR(IF(OR(AF7="",AG7=""),"",MAX(0,(MIN(AG7,TIME(24,0,0)+TIME(6,0,0))-MAX(AF7,TIME(22,0,0)))*24)+MAX(0,(MIN(AG7,TIME(6,0,0))-MAX(AF7,TIME(0,0,0)))*24)),"")
A8: =IFERROR(IF(DAY(DATE(2000+$F$1,$H$1+1,0))<5,"",DATE(2000+$F$1,$H$1,5)),"") -> 46117 | B8: =IF(A8="","",CHOOSE(WEEKDAY(A8),"일","월","화","수","목","금","토")) -> 일 | C8: =IF(A8="","",IF(OR(WEEKDAY(A8,2)>5,COUNTIF('2.공휴일리스트'!$A$2:$A$1000,A8)>0),"휴일","평일")) -> 휴일 | F8: =IFERROR(IF(OR(D8="",E8=""),"",IF($C8="평일",MIN(8,MAX(0,(E8-D8)*24-'1.설정(통합)'!$B$14)),0)),"") | G8: =IFERROR(IF(OR(D8="",E8="",$C8="휴일"),"",IF((E8-D8)*24-'1.설정(통합)'!$B$14>8,(E8-D8)*24-'1.설정(통합)'!$B$14-8,0)),"") | H8: =IFERROR(IF(OR(D8="",E8="",$C8="평일"),"",MIN(8,MAX(0,(E8-D8)*24-'1.설정(통합)'!$B$14))),"") | I8: =IFERROR(IF(OR(D8="",E8="",$C8="평일"),"",IF((E8-D8)*24-'1.설정(통합)'!$B$14>8,(E8-D8)*24-'1.설정(통합)'!$B$14-8,0)),"") | J8: =IFERROR(IF(OR(D8="",E8=""),"",MAX(0,(MIN(E8,TIME(24,0,0)+TIME(6,0,0))-MAX(D8,TIME(22,0,0)))*24)+MAX(0,(MIN(E8,TIME(6,0,0))-MAX(D8,TIME(0,0,0)))*24)),"") | M8: =IFERROR(IF(OR(K8="",L8=""),"",IF($C8="평일",MIN(8,MAX(0,(L8-K8)*24-'1.설정(통합)'!$C$14)),0)),"") | N8: =IFERROR(IF(OR(K8="",L8="",$C8="휴일"),"",IF((L8-K8)*24-'1.설정(통합)'!$C$14>8,(L8-K8)*24-'1.설정(통합)'!$C$14-8,0)),"") | O8: =IFERROR(IF(OR(K8="",L8="",$C8="평일"),"",MIN(8,MAX(0,(L8-K8)*24-'1.설정(통합)'!$C$14))),"") | P8: =IFERROR(IF(OR(K8="",L8="",$C8="평일"),"",IF((L8-K8)*24-'1.설정(통합)'!$C$14>8,(L8-K8)*24-'1.설정(통합)'!$C$14-8,0)),"") | Q8: =IFERROR(IF(OR(K8="",L8=""),"",MAX(0,(MIN(L8,TIME(24,0,0)+TIME(6,0,0))-MAX(K8,TIME(22,0,0)))*24)+MAX(0,(MIN(L8,TIME(6,0,0))-MAX(K8,TIME(0,0,0)))*24)),"") | T8: =IFERROR(IF(OR(R8="",S8=""),"",IF($C8="평일",MIN(8,MAX(0,(S8-R8)*24-'1.설정(통합)'!$D$14)),0)),"") | U8: =IFERROR(IF(OR(R8="",S8="",$C8="휴일"),"",IF((S8-R8)*24-'1.설정(통합)'!$D$14>8,(S8-R8)*24-'1.설정(통합)'!$D$14-8,0)),"") | V8: =IFERROR(IF(OR(R8="",S8="",$C8="평일"),"",MIN(8,MAX(0,(S8-R8)*24-'1.설정(통합)'!$D$14))),"") | W8: =IFERROR(IF(OR(R8="",S8="",$C8="평일"),"",IF((S8-R8)*24-'1.설정(통합)'!$D$14>8,(S8-R8)*24-'1.설정(통합)'!$D$14-8,0)),"") | X8: =IFERROR(IF(OR(R8="",S8=""),"",MAX(0,(MIN(S8,TIME(24,0,0)+TIME(6,0,0))-MAX(R8,TIME(22,0,0)))*24)+MAX(0,(MIN(S8,TIME(6,0,0))-MAX(R8,TIME(0,0,0)))*24)),"") | AA8: =IFERROR(IF(OR(Y8="",Z8=""),"",IF($C8="평일",MIN(8,MAX(0,(Z8-Y8)*24-'1.설정(통합)'!$E$14)),0)),"") | AB8: =IFERROR(IF(OR(Y8="",Z8="",$C8="휴일"),"",IF((Z8-Y8)*24-'1.설정(통합)'!$E$14>8,(Z8-Y8)*24-'1.설정(통합)'!$E$14-8,0)),"") | AC8: =IFERROR(IF(OR(Y8="",Z8="",$C8="평일"),"",MIN(8,MAX(0,(Z8-Y8)*24-'1.설정(통합)'!$E$14))),"") | AD8: =IFERROR(IF(OR(Y8="",Z8="",$C8="평일"),"",IF((Z8-Y8)*24-'1.설정(통합)'!$E$14>8,(Z8-Y8)*24-'1.설정(통합)'!$E$14-8,0)),"") | AE8: =IFERROR(IF(OR(Y8="",Z8=""),"",MAX(0,(MIN(Z8,TIME(24,0,0)+TIME(6,0,0))-MAX(Y8,TIME(22,0,0)))*24)+MAX(0,(MIN(Z8,TIME(6,0,0))-MAX(Y8,TIME(0,0,0)))*24)),"") | AH8: =IFERROR(IF(OR(AF8="",AG8=""),"",IF($C8="평일",MIN(8,MAX(0,(AG8-AF8)*24-'1.설정(통합)'!$F$14)),0)),"") | AI8: =IFERROR(IF(OR(AF8="",AG8="",$C8="휴일"),"",IF((AG8-AF8)*24-'1.설정(통합)'!$F$14>8,(AG8-AF8)*24-'1.설정(통합)'!$F$14-8,0)),"") | AJ8: =IFERROR(IF(OR(AF8="",AG8="",$C8="평일"),"",MIN(8,MAX(0,(AG8-AF8)*24-'1.설정(통합)'!$F$14))),"") | AK8: =IFERROR(IF(OR(AF8="",AG8="",$C8="평일"),"",IF((AG8-AF8)*24-'1.설정(통합)'!$F$14>8,(AG8-AF8)*24-'1.설정(통합)'!$F$14-8,0)),"") | AL8: =IFERROR(IF(OR(AF8="",AG8=""),"",MAX(0,(MIN(AG8,TIME(24,0,0)+TIME(6,0,0))-MAX(AF8,TIME(22,0,0)))*24)+MAX(0,(MIN(AG8,TIME(6,0,0))-MAX(AF8,TIME(0,0,0)))*24)),"")
A9: =IFERROR(IF(DAY(DATE(2000+$F$1,$H$1+1,0))<6,"",DATE(2000+$F$1,$H$1,6)),"") -> 46118 | B9: =IF(A9="","",CHOOSE(WEEKDAY(A9),"일","월","화","수","목","금","토")) -> 월 | C9: =IF(A9="","",IF(OR(WEEKDAY(A9,2)>5,COUNTIF('2.공휴일리스트'!$A$2:$A$1000,A9)>0),"휴일","평일")) -> 평일 | F9: =IFERROR(IF(OR(D9="",E9=""),"",IF($C9="평일",MIN(8,MAX(0,(E9-D9)*24-'1.설정(통합)'!$B$14)),0)),"") | G9: =IFERROR(IF(OR(D9="",E9="",$C9="휴일"),"",IF((E9-D9)*24-'1.설정(통합)'!$B$14>8,(E9-D9)*24-'1.설정(통합)'!$B$14-8,0)),"") | H9: =IFERROR(IF(OR(D9="",E9="",$C9="평일"),"",MIN(8,MAX(0,(E9-D9)*24-'1.설정(통합)'!$B$14))),"") | I9: =IFERROR(IF(OR(D9="",E9="",$C9="평일"),"",IF((E9-D9)*24-'1.설정(통합)'!$B$14>8,(E9-D9)*24-'1.설정(통합)'!$B$14-8,0)),"") | J9: =IFERROR(IF(OR(D9="",E9=""),"",MAX(0,(MIN(E9,TIME(24,0,0)+TIME(6,0,0))-MAX(D9,TIME(22,0,0)))*24)+MAX(0,(MIN(E9,TIME(6,0,0))-MAX(D9,TIME(0,0,0)))*24)),"") | K9: 0.33333333 | L9: 0.70833333 | M9: =IFERROR(IF(OR(K9="",L9=""),"",IF($C9="평일",MIN(8,MAX(0,(L9-K9)*24-'1.설정(통합)'!$C$14)),0)),"") -> 8 | N9: =IFERROR(IF(OR(K9="",L9="",$C9="휴일"),"",IF((L9-K9)*24-'1.설정(통합)'!$C$14>8,(L9-K9)*24-'1.설정(통합)'!$C$14-8,0)),"") -> 0 | O9: =IFERROR(IF(OR(K9="",L9="",$C9="평일"),"",MIN(8,MAX(0,(L9-K9)*24-'1.설정(통합)'!$C$14))),"") | P9: =IFERROR(IF(OR(K9="",L9="",$C9="평일"),"",IF((L9-K9)*24-'1.설정(통합)'!$C$14>8,(L9-K9)*24-'1.설정(통합)'!$C$14-8,0)),"") | Q9: =IFERROR(IF(OR(K9="",L9=""),"",MAX(0,(MIN(L9,TIME(24,0,0)+TIME(6,0,0))-MAX(K9,TIME(22,0,0)))*24)+MAX(0,(MIN(L9,TIME(6,0,0))-MAX(K9,TIME(0,0,0)))*24)),"") -> 0 | T9: =IFERROR(IF(OR(R9="",S9=""),"",IF($C9="평일",MIN(8,MAX(0,(S9-R9)*24-'1.설정(통합)'!$D$14)),0)),"") | U9: =IFERROR(IF(OR(R9="",S9="",$C9="휴일"),"",IF((S9-R9)*24-'1.설정(통합)'!$D$14>8,(S9-R9)*24-'1.설정(통합)'!$D$14-8,0)),"") | V9: =IFERROR(IF(OR(R9="",S9="",$C9="평일"),"",MIN(8,MAX(0,(S9-R9)*24-'1.설정(통합)'!$D$14))),"") | W9: =IFERROR(IF(OR(R9="",S9="",$C9="평일"),"",IF((S9-R9)*24-'1.설정(통합)'!$D$14>8,(S9-R9)*24-'1.설정(통합)'!$D$14-8,0)),"") | X9: =IFERROR(IF(OR(R9="",S9=""),"",MAX(0,(MIN(S9,TIME(24,0,0)+TIME(6,0,0))-MAX(R9,TIME(22,0,0)))*24)+MAX(0,(MIN(S9,TIME(6,0,0))-MAX(R9,TIME(0,0,0)))*24)),"") | AA9: =IFERROR(IF(OR(Y9="",Z9=""),"",IF($C9="평일",MIN(8,MAX(0,(Z9-Y9)*24-'1.설정(통합)'!$E$14)),0)),"") | AB9: =IFERROR(IF(OR(Y9="",Z9="",$C9="휴일"),"",IF((Z9-Y9)*24-'1.설정(통합)'!$E$14>8,(Z9-Y9)*24-'1.설정(통합)'!$E$14-8,0)),"") | AC9: =IFERROR(IF(OR(Y9="",Z9="",$C9="평일"),"",MIN(8,MAX(0,(Z9-Y9)*24-'1.설정(통합)'!$E$14))),"") | AD9: =IFERROR(IF(OR(Y9="",Z9="",$C9="평일"),"",IF((Z9-Y9)*24-'1.설정(통합)'!$E$14>8,(Z9-Y9)*24-'1.설정(통합)'!$E$14-8,0)),"") | AE9: =IFERROR(IF(OR(Y9="",Z9=""),"",MAX(0,(MIN(Z9,TIME(24,0,0)+TIME(6,0,0))-MAX(Y9,TIME(22,0,0)))*24)+MAX(0,(MIN(Z9,TIME(6,0,0))-MAX(Y9,TIME(0,0,0)))*24)),"") | AF9: 0.33333333 | AG9: 0.70833333 | AH9: =IFERROR(IF(OR(AF9="",AG9=""),"",IF($C9="평일",MIN(8,MAX(0,(AG9-AF9)*24-'1.설정(통합)'!$F$14)),0)),"") -> 8 | AI9: =IFERROR(IF(OR(AF9="",AG9="",$C9="휴일"),"",IF((AG9-AF9)*24-'1.설정(통합)'!$F$14>8,(AG9-AF9)*24-'1.설정(통합)'!$F$14-8,0)),"") -> 0 | AJ9: =IFERROR(IF(OR(AF9="",AG9="",$C9="평일"),"",MIN(8,MAX(0,(AG9-AF9)*24-'1.설정(통합)'!$F$14))),"") | AK9: =IFERROR(IF(OR(AF9="",AG9="",$C9="평일"),"",IF((AG9-AF9)*24-'1.설정(통합)'!$F$14>8,(AG9-AF9)*24-'1.설정(통합)'!$F$14-8,0)),"") | AL9: =IFERROR(IF(OR(AF9="",AG9=""),"",MAX(0,(MIN(AG9,TIME(24,0,0)+TIME(6,0,0))-MAX(AF9,TIME(22,0,0)))*24)+MAX(0,(MIN(AG9,TIME(6,0,0))-MAX(AF9,TIME(0,0,0)))*24)),"") -> 0
A10: =IFERROR(IF(DAY(DATE(2000+$F$1,$H$1+1,0))<7,"",DATE(2000+$F$1,$H$1,7)),"") -> 46119 | B10: =IF(A10="","",CHOOSE(WEEKDAY(A10),"일","월","화","수","목","금","토")) -> 화 | C10: =IF(A10="","",IF(OR(WEEKDAY(A10,2)>5,COUNTIF('2.공휴일리스트'!$A$2:$A$1000,A10)>0),"휴일","평일")) -> 평일 | F10: =IFERROR(IF(OR(D10="",E10=""),"",IF($C10="평일",MIN(8,MAX(0,(E10-D10)*24-'1.설정(통합)'!$B$14)),0)),"") | G10: =IFERROR(IF(OR(D10="",E10="",$C10="휴일"),"",IF((E10-D10)*24-'1.설정(통합)'!$B$14>8,(E10-D10)*24-'1.설정(통합)'!$B$14-8,0)),"") | H10: =IFERROR(IF(OR(D10="",E10="",$C10="평일"),"",MIN(8,MAX(0,(E10-D10)*24-'1.설정(통합)'!$B$14))),"") | I10: =IFERROR(IF(OR(D10="",E10="",$C10="평일"),"",IF((E10-D10)*24-'1.설정(통합)'!$B$14>8,(E10-D10)*24-'1.설정(통합)'!$B$14-8,0)),"") | J10: =IFERROR(IF(OR(D10="",E10=""),"",MAX(0,(MIN(E10,TIME(24,0,0)+TIME(6,0,0))-MAX(D10,TIME(22,0,0)))*24)+MAX(0,(MIN(E10,TIME(6,0,0))-MAX(D10,TIME(0,0,0)))*24)),"") | K10: 0.33333333 | L10: 0.70833333 | M10: =IFERROR(IF(OR(K10="",L10=""),"",IF($C10="평일",MIN(8,MAX(0,(L10-K10)*24-'1.설정(통합)'!$C$14)),0)),"") -> 8 | N10: =IFERROR(IF(OR(K10="",L10="",$C10="휴일"),"",IF((L10-K10)*24-'1.설정(통합)'!$C$14>8,(L10-K10)*24-'1.설정(통합)'!$C$14-8,0)),"") -> 0 | O10: =IFERROR(IF(OR(K10="",L10="",$C10="평일"),"",MIN(8,MAX(0,(L10-K10)*24-'1.설정(통합)'!$C$14))),"") | P10: =IFERROR(IF(OR(K10="",L10="",$C10="평일"),"",IF((L10-K10)*24-'1.설정(통합)'!$C$14>8,(L10-K10)*24-'1.설정(통합)'!$C$14-8,0)),"") | Q10: =IFERROR(IF(OR(K10="",L10=""),"",MAX(0,(MIN(L10,TIME(24,0,0)+TIME(6,0,0))-MAX(K10,TIME(22,0,0)))*24)+MAX(0,(MIN(L10,TIME(6,0,0))-MAX(K10,TIME(0,0,0)))*24)),"") -> 0 | T10: =IFERROR(IF(OR(R10="",S10=""),"",IF($C10="평일",MIN(8,MAX(0,(S10-R10)*24-'1.설정(통합)'!$D$14)),0)),"") | U10: =IFERROR(IF(OR(R10="",S10="",$C10="휴일"),"",IF((S10-R10)*24-'1.설정(통합)'!$D$14>8,(S10-R10)*24-'1.설정(통합)'!$D$14-8,0)),"") | V10: =IFERROR(IF(OR(R10="",S10="",$C10="평일"),"",MIN(8,MAX(0,(S10-R10)*24-'1.설정(통합)'!$D$14))),"") | W10: =IFERROR(IF(OR(R10="",S10="",$C10="평일"),"",IF((S10-R10)*24-'1.설정(통합)'!$D$14>8,(S10-R10)*24-'1.설정(통합)'!$D$14-8,0)),"") | X10: =IFERROR(IF(OR(R10="",S10=""),"",MAX(0,(MIN(S10,TIME(24,0,0)+TIME(6,0,0))-MAX(R10,TIME(22,0,0)))*24)+MAX(0,(MIN(S10,TIME(6,0,0))-MAX(R10,TIME(0,0,0)))*24)),"") | Y10: 0.33333333 | Z10: 0.70833333 | AA10: =IFERROR(IF(OR(Y10="",Z10=""),"",IF($C10="평일",MIN(8,MAX(0,(Z10-Y10)*24-'1.설정(통합)'!$E$14)),0)),"") -> 8 | AB10: =IFERROR(IF(OR(Y10="",Z10="",$C10="휴일"),"",IF((Z10-Y10)*24-'1.설정(통합)'!$E$14>8,(Z10-Y10)*24-'1.설정(통합)'!$E$14-8,0)),"") -> 0 | AC10: =IFERROR(IF(OR(Y10="",Z10="",$C10="평일"),"",MIN(8,MAX(0,(Z10-Y10)*24-'1.설정(통합)'!$E$14))),"") | AD10: =IFERROR(IF(OR(Y10="",Z10="",$C10="평일"),"",IF((Z10-Y10)*24-'1.설정(통합)'!$E$14>8,(Z10-Y10)*24-'1.설정(통합)'!$E$14-8,0)),"") | AE10: =IFERROR(IF(OR(Y10="",Z10=""),"",MAX(0,(MIN(Z10,TIME(24,0,0)+TIME(6,0,0))-MAX(Y10,TIME(22,0,0)))*24)+MAX(0,(MIN(Z10,TIME(6,0,0))-MAX(Y10,TIME(0,0,0)))*24)),"") -> 0 | AF10: 0.33333333 | AG10: 0.70833333 | AH10: =IFERROR(IF(OR(AF10="",AG10=""),"",IF($C10="평일",MIN(8,MAX(0,(AG10-AF10)*24-'1.설정(통합)'!$F$14)),0)),"") -> 8 | AI10: =IFERROR(IF(OR(AF10="",AG10="",$C10="휴일"),"",IF((AG10-AF10)*24-'1.설정(통합)'!$F$14>8,(AG10-AF10)*24-'1.설정(통합)'!$F$14-8,0)),"") -> 0 | AJ10: =IFERROR(IF(OR(AF10="",AG10="",$C10="평일"),"",MIN(8,MAX(0,(AG10-AF10)*24-'1.설정(통합)'!$F$14))),"") | AK10: =IFERROR(IF(OR(AF10="",AG10="",$C10="평일"),"",IF((AG10-AF10)*24-'1.설정(통합)'!$F$14>8,(AG10-AF10)*24-'1.설정(통합)'!$F$14-8,0)),"") | AL10: =IFERROR(IF(OR(AF10="",AG10=""),"",MAX(0,(MIN(AG10,TIME(24,0,0)+TIME(6,0,0))-MAX(AF10,TIME(22,0,0)))*24)+MAX(0,(MIN(AG10,TIME(6,0,0))-MAX(AF10,TIME(0,0,0)))*24)),"") -> 0
A11: =IFERROR(IF(DAY(DATE(2000+$F$1,$H$1+1,0))<8,"",DATE(2000+$F$1,$H$1,8)),"") -> 46120 | B11: =IF(A11="","",CHOOSE(WEEKDAY(A11),"일","월","화","수","목","금","토")) -> 수 | C11: =IF(A11="","",IF(OR(WEEKDAY(A11,2)>5,COUNTIF('2.공휴일리스트'!$A$2:$A$1000,A11)>0),"휴일","평일")) -> 평일 | F11: =IFERROR(IF(OR(D11="",E11=""),"",IF($C11="평일",MIN(8,MAX(0,(E11-D11)*24-'1.설정(통합)'!$B$14)),0)),"") | G11: =IFERROR(IF(OR(D11="",E11="",$C11="휴일"),"",IF((E11-D11)*24-'1.설정(통합)'!$B$14>8,(E11-D11)*24-'1.설정(통합)'!$B$14-8,0)),"") | H11: =IFERROR(IF(OR(D11="",E11="",$C11="평일"),"",MIN(8,MAX(0,(E11-D11)*24-'1.설정(통합)'!$B$14))),"") | I11: =IFERROR(IF(OR(D11="",E11="",$C11="평일"),"",IF((E11-D11)*24-'1.설정(통합)'!$B$14>8,(E11-D11)*24-'1.설정(통합)'!$B$14-8,0)),"") | J11: =IFERROR(IF(OR(D11="",E11=""),"",MAX(0,(MIN(E11,TIME(24,0,0)+TIME(6,0,0))-MAX(D11,TIME(22,0,0)))*24)+MAX(0,(MIN(E11,TIME(6,0,0))-MAX(D11,TIME(0,0,0)))*24)),"") | K11: 0.33333333 | L11: 0.70833333 | M11: =IFERROR(IF(OR(K11="",L11=""),"",IF($C11="평일",MIN(8,MAX(0,(L11-K11)*24-'1.설정(통합)'!$C$14)),0)),"") -> 8 | N11: =IFERROR(IF(OR(K11="",L11="",$C11="휴일"),"",IF((L11-K11)*24-'1.설정(통합)'!$C$14>8,(L11-K11)*24-'1.설정(통합)'!$C$14-8,0)),"") -> 0 | O11: =IFERROR(IF(OR(K11="",L11="",$C11="평일"),"",MIN(8,MAX(0,(L11-K11)*24-'1.설정(통합)'!$C$14))),"") | P11: =IFERROR(IF(OR(K11="",L11="",$C11="평일"),"",IF((L11-K11)*24-'1.설정(통합)'!$C$14>8,(L11-K11)*24-'1.설정(통합)'!$C$14-8,0)),"") | Q11: =IFERROR(IF(OR(K11="",L11=""),"",MAX(0,(MIN(L11,TIME(24,0,0)+TIME(6,0,0))-MAX(K11,TIME(22,0,0)))*24)+MAX(0,(MIN(L11,TIME(6,0,0))-MAX(K11,TIME(0,0,0)))*24)),"") -> 0 | T11: =IFERROR(IF(OR(R11="",S11=""),"",IF($C11="평일",MIN(8,MAX(0,(S11-R11)*24-'1.설정(통합)'!$D$14)),0)),"") | U11: =IFERROR(IF(OR(R11="",S11="",$C11="휴일"),"",IF((S11-R11)*24-'1.설정(통합)'!$D$14>8,(S11-R11)*24-'1.설정(통합)'!$D$14-8,0)),"") | V11: =IFERROR(IF(OR(R11="",S11="",$C11="평일"),"",MIN(8,MAX(0,(S11-R11)*24-'1.설정(통합)'!$D$14))),"") | W11: =IFERROR(IF(OR(R11="",S11="",$C11="평일"),"",IF((S11-R11)*24-'1.설정(통합)'!$D$14>8,(S11-R11)*24-'1.설정(통합)'!$D$14-8,0)),"") | X11: =IFERROR(IF(OR(R11="",S11=""),"",MAX(0,(MIN(S11,TIME(24,0,0)+TIME(6,0,0))-MAX(R11,TIME(22,0,0)))*24)+MAX(0,(MIN(S11,TIME(6,0,0))-MAX(R11,TIME(0,0,0)))*24)),"") | Y11: 0.33333333 | Z11: 0.70833333 | AA11: =IFERROR(IF(OR(Y11="",Z11=""),"",IF($C11="평일",MIN(8,MAX(0,(Z11-Y11)*24-'1.설정(통합)'!$E$14)),0)),"") -> 8 | AB11: =IFERROR(IF(OR(Y11="",Z11="",$C11="휴일"),"",IF((Z11-Y11)*24-'1.설정(통합)'!$E$14>8,(Z11-Y11)*24-'1.설정(통합)'!$E$14-8,0)),"") -> 0 | AC11: =IFERROR(IF(OR(Y11="",Z11="",$C11="평일"),"",MIN(8,MAX(0,(Z11-Y11)*24-'1.설정(통합)'!$E$14))),"") | AD11: =IFERROR(IF(OR(Y11="",Z11="",$C11="평일"),"",IF((Z11-Y11)*24-'1.설정(통합)'!$E$14>8,(Z11-Y11)*24-'1.설정(통합)'!$E$14-8,0)),"") | AE11: =IFERROR(IF(OR(Y11="",Z11=""),"",MAX(0,(MIN(Z11,TIME(24,0,0)+TIME(6,0,0))-MAX(Y11,TIME(22,0,0)))*24)+MAX(0,(MIN(Z11,TIME(6,0,0))-MAX(Y11,TIME(0,0,0)))*24)),"") -> 0 | AF11: 0.33333333 | AG11: 0.70833333 | AH11: =IFERROR(IF(OR(AF11="",AG11=""),"",IF($C11="평일",MIN(8,MAX(0,(AG11-AF11)*24-'1.설정(통합)'!$F$14)),0)),"") -> 8 | AI11: =IFERROR(IF(OR(AF11="",AG11="",$C11="휴일"),"",IF((AG11-AF11)*24-'1.설정(통합)'!$F$14>8,(AG11-AF11)*24-'1.설정(통합)'!$F$14-8,0)),"") -> 0 | AJ11: =IFERROR(IF(OR(AF11="",AG11="",$C11="평일"),"",MIN(8,MAX(0,(AG11-AF11)*24-'1.설정(통합)'!$F$14))),"") | AK11: =IFERROR(IF(OR(AF11="",AG11="",$C11="평일"),"",IF((AG11-AF11)*24-'1.설정(통합)'!$F$14>8,(AG11-AF11)*24-'1.설정(통합)'!$F$14-8,0)),"") | AL11: =IFERROR(IF(OR(AF11="",AG11=""),"",MAX(0,(MIN(AG11,TIME(24,0,0)+TIME(6,0,0))-MAX(AF11,TIME(22,0,0)))*24)+MAX(0,(MIN(AG11,TIME(6,0,0))-MAX(AF11,TIME(0,0,0)))*24)),"") -> 0
A12: =IFERROR(IF(DAY(DATE(2000+$F$1,$H$1+1,0))<9,"",DATE(2000+$F$1,$H$1,9)),"") -> 46121 | B12: =IF(A12="","",CHOOSE(WEEKDAY(A12),"일","월","화","수","목","금","토")) -> 목 | C12: =IF(A12="","",IF(OR(WEEKDAY(A12,2)>5,COUNTIF('2.공휴일리스트'!$A$2:$A$1000,A12)>0),"휴일","평일")) -> 평일 | F12: =IFERROR(IF(OR(D12="",E12=""),"",IF($C12="평일",MIN(8,MAX(0,(E12-D12)*24-'1.설정(통합)'!$B$14)),0)),"") | G12: =IFERROR(IF(OR(D12="",E12="",$C12="휴일"),"",IF((E12-D12)*24-'1.설정(통합)'!$B$14>8,(E12-D12)*24-'1.설정(통합)'!$B$14-8,0)),"") | H12: =IFERROR(IF(OR(D12="",E12="",$C12="평일"),"",MIN(8,MAX(0,(E12-D12)*24-'1.설정(통합)'!$B$14))),"") | I12: =IFERROR(IF(OR(D12="",E12="",$C12="평일"),"",IF((E12-D12)*24-'1.설정(통합)'!$B$14>8,(E12-D12)*24-'1.설정(통합)'!$B$14-8,0)),"") | J12: =IFERROR(IF(OR(D12="",E12=""),"",MAX(0,(MIN(E12,TIME(24,0,0)+TIME(6,0,0))-MAX(D12,TIME(22,0,0)))*24)+MAX(0,(MIN(E12,TIME(6,0,0))-MAX(D12,TIME(0,0,0)))*24)),"") | K12: 0.33333333 | L12: 0.70833333 | M12: =IFERROR(IF(OR(K12="",L12=""),"",IF($C12="평일",MIN(8,MAX(0,(L12-K12)*24-'1.설정(통합)'!$C$14)),0)),"") -> 8 | N12: =IFERROR(IF(OR(K12="",L12="",$C12="휴일"),"",IF((L12-K12)*24-'1.설정(통합)'!$C$14>8,(L12-K12)*24-'1.설정(통합)'!$C$14-8,0)),"") -> 0 | O12: =IFERROR(IF(OR(K12="",L12="",$C12="평일"),"",MIN(8,MAX(0,(L12-K12)*24-'1.설정(통합)'!$C$14))),"") | P12: =IFERROR(IF(OR(K12="",L12="",$C12="평일"),"",IF((L12-K12)*24-'1.설정(통합)'!$C$14>8,(L12-K12)*24-'1.설정(통합)'!$C$14-8,0)),"") | Q12: =IFERROR(IF(OR(K12="",L12=""),"",MAX(0,(MIN(L12,TIME(24,0,0)+TIME(6,0,0))-MAX(K12,TIME(22,0,0)))*24)+MAX(0,(MIN(L12,TIME(6,0,0))-MAX(K12,TIME(0,0,0)))*24)),"") -> 0 | T12: =IFERROR(IF(OR(R12="",S12=""),"",IF($C12="평일",MIN(8,MAX(0,(S12-R12)*24-'1.설정(통합)'!$D$14)),0)),"") | U12: =IFERROR(IF(OR(R12="",S12="",$C12="휴일"),"",IF((S12-R12)*24-'1.설정(통합)'!$D$14>8,(S12-R12)*24-'1.설정(통합)'!$D$14-8,0)),"") | V12: =IFERROR(IF(OR(R12="",S12="",$C12="평일"),"",MIN(8,MAX(0,(S12-R12)*24-'1.설정(통합)'!$D$14))),"") | W12: =IFERROR(IF(OR(R12="",S12="",$C12="평일"),"",IF((S12-R12)*24-'1.설정(통합)'!$D$14>8,(S12-R12)*24-'1.설정(통합)'!$D$14-8,0)),"") | X12: =IFERROR(IF(OR(R12="",S12=""),"",MAX(0,(MIN(S12,TIME(24,0,0)+TIME(6,0,0))-MAX(R12,TIME(22,0,0)))*24)+MAX(0,(MIN(S12,TIME(6,0,0))-MAX(R12,TIME(0,0,0)))*24)),"") | Y12: 0.33333333 | Z12: 0.70833333 | AA12: =IFERROR(IF(OR(Y12="",Z12=""),"",IF($C12="평일",MIN(8,MAX(0,(Z12-Y12)*24-'1.설정(통합)'!$E$14)),0)),"") -> 8 | AB12: =IFERROR(IF(OR(Y12="",Z12="",$C12="휴일"),"",IF((Z12-Y12)*24-'1.설정(통합)'!$E$14>8,(Z12-Y12)*24-'1.설정(통합)'!$E$14-8,0)),"") -> 0 | AC12: =IFERROR(IF(OR(Y12="",Z12="",$C12="평일"),"",MIN(8,MAX(0,(Z12-Y12)*24-'1.설정(통합)'!$E$14))),"") | AD12: =IFERROR(IF(OR(Y12="",Z12="",$C12="평일"),"",IF((Z12-Y12)*24-'1.설정(통합)'!$E$14>8,(Z12-Y12)*24-'1.설정(통합)'!$E$14-8,0)),"") | AE12: =IFERROR(IF(OR(Y12="",Z12=""),"",MAX(0,(MIN(Z12,TIME(24,0,0)+TIME(6,0,0))-MAX(Y12,TIME(22,0,0)))*24)+MAX(0,(MIN(Z12,TIME(6,0,0))-MAX(Y12,TIME(0,0,0)))*24)),"") -> 0 | AF12: 0.33333333 | AG12: 0.70833333 | AH12: =IFERROR(IF(OR(AF12="",AG12=""),"",IF($C12="평일",MIN(8,MAX(0,(AG12-AF12)*24-'1.설정(통합)'!$F$14)),0)),"") -> 8 | AI12: =IFERROR(IF(OR(AF12="",AG12="",$C12="휴일"),"",IF((AG12-AF12)*24-'1.설정(통합)'!$F$14>8,(AG12-AF12)*24-'1.설정(통합)'!$F$14-8,0)),"") -> 0 | AJ12: =IFERROR(IF(OR(AF12="",AG12="",$C12="평일"),"",MIN(8,MAX(0,(AG12-AF12)*24-'1.설정(통합)'!$F$14))),"") | AK12: =IFERROR(IF(OR(AF12="",AG12="",$C12="평일"),"",IF((AG12-AF12)*24-'1.설정(통합)'!$F$14>8,(AG12-AF12)*24-'1.설정(통합)'!$F$14-8,0)),"") | AL12: =IFERROR(IF(OR(AF12="",AG12=""),"",MAX(0,(MIN(AG12,TIME(24,0,0)+TIME(6,0,0))-MAX(AF12,TIME(22,0,0)))*24)+MAX(0,(MIN(AG12,TIME(6,0,0))-MAX(AF12,TIME(0,0,0)))*24)),"") -> 0
A13: =IFERROR(IF(DAY(DATE(2000+$F$1,$H$1+1,0))<10,"",DATE(2000+$F$1,$H$1,10)),"") -> 46122 | B13: =IF(A13="","",CHOOSE(WEEKDAY(A13),"일","월","화","수","목","금","토")) -> 금 | C13: =IF(A13="","",IF(OR(WEEKDAY(A13,2)>5,COUNTIF('2.공휴일리스트'!$A$2:$A$1000,A13)>0),"휴일","평일")) -> 평일 | F13: =IFERROR(IF(OR(D13="",E13=""),"",IF($C13="평일",MIN(8,MAX(0,(E13-D13)*24-'1.설정(통합)'!$B$14)),0)),"") | G13: =IFERROR(IF(OR(D13="",E13="",$C13="휴일"),"",IF((E13-D13)*24-'1.설정(통합)'!$B$14>8,(E13-D13)*24-'1.설정(통합)'!$B$14-8,0)),"") | H13: =IFERROR(IF(OR(D13="",E13="",$C13="평일"),"",MIN(8,MAX(0,(E13-D13)*24-'1.설정(통합)'!$B$14))),"") | I13: =IFERROR(IF(OR(D13="",E13="",$C13="평일"),"",IF((E13-D13)*24-'1.설정(통합)'!$B$14>8,(E13-D13)*24-'1.설정(통합)'!$B$14-8,0)),"") | J13: =IFERROR(IF(OR(D13="",E13=""),"",MAX(0,(MIN(E13,TIME(24,0,0)+TIME(6,0,0))-MAX(D13,TIME(22,0,0)))*24)+MAX(0,(MIN(E13,TIME(6,0,0))-MAX(D13,TIME(0,0,0)))*24)),"") | K13: 0.33333333 | L13: 0.70833333 | M13: =IFERROR(IF(OR(K13="",L13=""),"",IF($C13="평일",MIN(8,MAX(0,(L13-K13)*24-'1.설정(통합)'!$C$14)),0)),"") -> 8 | N13: =IFERROR(IF(OR(K13="",L13="",$C13="휴일"),"",IF((L13-K13)*24-'1.설정(통합)'!$C$14>8,(L13-K13)*24-'1.설정(통합)'!$C$14-8,0)),"") -> 0 | O13: =IFERROR(IF(OR(K13="",L13="",$C13="평일"),"",MIN(8,MAX(0,(L13-K13)*24-'1.설정(통합)'!$C$14))),"") | P13: =IFERROR(IF(OR(K13="",L13="",$C13="평일"),"",IF((L13-K13)*24-'1.설정(통합)'!$C$14>8,(L13-K13)*24-'1.설정(통합)'!$C$14-8,0)),"") | Q13: =IFERROR(IF(OR(K13="",L13=""),"",MAX(0,(MIN(L13,TIME(24,0,0)+TIME(6,0,0))-MAX(K13,TIME(22,0,0)))*24)+MAX(0,(MIN(L13,TIME(6,0,0))-MAX(K13,TIME(0,0,0)))*24)),"") -> 0 | R13: 0.33333333 | S13: 0.70833333 | T13: =IFERROR(IF(OR(R13="",S13=""),"",IF($C13="평일",MIN(8,MAX(0,(S13-R13)*24-'1.설정(통합)'!$D$14)),0)),"") -> 8 | U13: =IFERROR(IF(OR(R13="",S13="",$C13="휴일"),"",IF((S13-R13)*24-'1.설정(통합)'!$D$14>8,(S13-R13)*24-'1.설정(통합)'!$D$14-8,0)),"") -> 0 | V13: =IFERROR(IF(OR(R13="",S13="",$C13="평일"),"",MIN(8,MAX(0,(S13-R13)*24-'1.설정(통합)'!$D$14))),"") | W13: =IFERROR(IF(OR(R13="",S13="",$C13="평일"),"",IF((S13-R13)*24-'1.설정(통합)'!$D$14>8,(S13-R13)*24-'1.설정(통합)'!$D$14-8,0)),"") | X13: =IFERROR(IF(OR(R13="",S13=""),"",MAX(0,(MIN(S13,TIME(24,0,0)+TIME(6,0,0))-MAX(R13,TIME(22,0,0)))*24)+MAX(0,(MIN(S13,TIME(6,0,0))-MAX(R13,TIME(0,0,0)))*24)),"") -> 0 | Y13: 0.33333333 | Z13: 0.8125 | AA13: =IFERROR(IF(OR(Y13="",Z13=""),"",IF($C13="평일",MIN(8,MAX(0,(Z13-Y13)*24-'1.설정(통합)'!$E$14)),0)),"") -> 8 | AB13: =IFERROR(IF(OR(Y13="",Z13="",$C13="휴일"),"",IF((Z13-Y13)*24-'1.설정(통합)'!$E$14>8,(Z13-Y13)*24-'1.설정(통합)'!$E$14-8,0)),"") -> 2.5 | AC13: =IFERROR(IF(OR(Y13="",Z13="",$C13="평일"),"",MIN(8,MAX(0,(Z13-Y13)*24-'1.설정(통합)'!$E$14))),"") | AD13: =IFERROR(IF(OR(Y13="",Z13="",$C13="평일"),"",IF((Z13-Y13)*24-'1.설정(통합)'!$E$14>8,(Z13-Y13)*24-'1.설정(통합)'!$E$14-8,0)),"") | AE13: =IFERROR(IF(OR(Y13="",Z13=""),"",MAX(0,(MIN(Z13,TIME(24,0,0)+TIME(6,0,0))-MAX(Y13,TIME(22,0,0)))*24)+MAX(0,(MIN(Z13,TIME(6,0,0))-MAX(Y13,TIME(0,0,0)))*24)),"") -> 0 | AF13: 0.33333333 | AG13: 0.70833333 | AH13: =IFERROR(IF(OR(AF13="",AG13=""),"",IF($C13="평일",MIN(8,MAX(0,(AG13-AF13)*24-'1.설정(통합)'!$F$14)),0)),"") -> 8 | AI13: =IFERROR(IF(OR(AF13="",AG13="",$C13="휴일"),"",IF((AG13-AF13)*24-'1.설정(통합)'!$F$14>8,(AG13-AF13)*24-'1.설정(통합)'!$F$14-8,0)),"") -> 0 | AJ13: =IFERROR(IF(OR(AF13="",AG13="",$C13="평일"),"",MIN(8,MAX(0,(AG13-AF13)*24-'1.설정(통합)'!$F$14))),"") | AK13: =IFERROR(IF(OR(AF13="",AG13="",$C13="평일"),"",IF((AG13-AF13)*24-'1.설정(통합)'!$F$14>8,(AG13-AF13)*24-'1.설정(통합)'!$F$14-8,0)),"") | AL13: =IFERROR(IF(OR(AF13="",AG13=""),"",MAX(0,(MIN(AG13,TIME(24,0,0)+TIME(6,0,0))-MAX(AF13,TIME(22,0,0)))*24)+MAX(0,(MIN(AG13,TIME(6,0,0))-MAX(AF13,TIME(0,0,0)))*24)),"") -> 0
A14: =IFERROR(IF(DAY(DATE(2000+$F$1,$H$1+1,0))<11,"",DATE(2000+$F$1,$H$1,11)),"") -> 46123 | B14: =IF(A14="","",CHOOSE(WEEKDAY(A14),"일","월","화","수","목","금","토")) -> 토 | C14: =IF(A14="","",IF(OR(WEEKDAY(A14,2)>5,COUNTIF('2.공휴일리스트'!$A$2:$A$1000,A14)>0),"휴일","평일")) -> 휴일 | F14: =IFERROR(IF(OR(D14="",E14=""),"",IF($C14="평일",MIN(8,MAX(0,(E14-D14)*24-'1.설정(통합)'!$B$14)),0)),"") | G14: =IFERROR(IF(OR(D14="",E14="",$C14="휴일"),"",IF((E14-D14)*24-'1.설정(통합)'!$B$14>8,(E14-D14)*24-'1.설정(통합)'!$B$14-8,0)),"") | H14: =IFERROR(IF(OR(D14="",E14="",$C14="평일"),"",MIN(8,MAX(0,(E14-D14)*24-'1.설정(통합)'!$B$14))),"") | I14: =IFERROR(IF(OR(D14="",E14="",$C14="평일"),"",IF((E14-D14)*24-'1.설정(통합)'!$B$14>8,(E14-D14)*24-'1.설정(통합)'!$B$14-8,0)),"") | J14: =IFERROR(IF(OR(D14="",E14=""),"",MAX(0,(MIN(E14,TIME(24,0,0)+TIME(6,0,0))-MAX(D14,TIME(22,0,0)))*24)+MAX(0,(MIN(E14,TIME(6,0,0))-MAX(D14,TIME(0,0,0)))*24)),"") | K14: 0.33333333 | L14: 0.66666667 | M14: =IFERROR(IF(OR(K14="",L14=""),"",IF($C14="평일",MIN(8,MAX(0,(L14-K14)*24-'1.설정(통합)'!$C$14)),0)),"") -> 0 | N14: =IFERROR(IF(OR(K14="",L14="",$C14="휴일"),"",IF((L14-K14)*24-'1.설정(통합)'!$C$14>8,(L14-K14)*24-'1.설정(통합)'!$C$14-8,0)),"") | O14: =IFERROR(IF(OR(K14="",L14="",$C14="평일"),"",MIN(8,MAX(0,(L14-K14)*24-'1.설정(통합)'!$C$14))),"") -> 7 | P14: =IFERROR(IF(OR(K14="",L14="",$C14="평일"),"",IF((L14-K14)*24-'1.설정(통합)'!$C$14>8,(L14-K14)*24-'1.설정(통합)'!$C$14-8,0)),"") -> 0 | Q14: =IFERROR(IF(OR(K14="",L14=""),"",MAX(0,(MIN(L14,TIME(24,0,0)+TIME(6,0,0))-MAX(K14,TIME(22,0,0)))*24)+MAX(0,(MIN(L14,TIME(6,0,0))-MAX(K14,TIME(0,0,0)))*24)),"") -> 0 | R14: 0.33333333 | S14: 0.66666667 | T14: =IFERROR(IF(OR(R14="",S14=""),"",IF($C14="평일",MIN(8,MAX(0,(S14-R14)*24-'1.설정(통합)'!$D$14)),0)),"") -> 0 | U14: =IFERROR(IF(OR(R14="",S14="",$C14="휴일"),"",IF((S14-R14)*24-'1.설정(통합)'!$D$14>8,(S14-R14)*24-'1.설정(통합)'!$D$14-8,0)),"") | V14: =IFERROR(IF(OR(R14="",S14="",$C14="평일"),"",MIN(8,MAX(0,(S14-R14)*24-'1.설정(통합)'!$D$14))),"") -> 7 | W14: =IFERROR(IF(OR(R14="",S14="",$C14="평일"),"",IF((S14-R14)*24-'1.설정(통합)'!$D$14>8,(S14-R14)*24-'1.설정(통합)'!$D$14-8,0)),"") -> 0 | X14: =IFERROR(IF(OR(R14="",S14=""),"",MAX(0,(MIN(S14,TIME(24,0,0)+TIME(6,0,0))-MAX(R14,TIME(22,0,0)))*24)+MAX(0,(MIN(S14,TIME(6,0,0))-MAX(R14,TIME(0,0,0)))*24)),"") -> 0 | Y14: 0.33333333 | Z14: 0.66666667 | AA14: =IFERROR(IF(OR(Y14="",Z14=""),"",IF($C14="평일",MIN(8,MAX(0,(Z14-Y14)*24-'1.설정(통합)'!$E$14)),0)),"") -> 0 | AB14: =IFERROR(IF(OR(Y14="",Z14="",$C14="휴일"),"",IF((Z14-Y14)*24-'1.설정(통합)'!$E$14>8,(Z14-Y14)*24-'1.설정(통합)'!$E$14-8,0)),"") | AC14: =IFERROR(IF(OR(Y14="",Z14="",$C14="평일"),"",MIN(8,MAX(0,(Z14-Y14)*24-'1.설정(통합)'!$E$14))),"") -> 7 | AD14: =IFERROR(IF(OR(Y14="",Z14="",$C14="평일"),"",IF((Z14-Y14)*24-'1.설정(통합)'!$E$14>8,(Z14-Y14)*24-'1.설정(통합)'!$E$14-8,0)),"") -> 0 | AE14: =IFERROR(IF(OR(Y14="",Z14=""),"",MAX(0,(MIN(Z14,TIME(24,0,0)+TIME(6,0,0))-MAX(Y14,TIME(22,0,0)))*24)+MAX(0,(MIN(Z14,TIME(6,0,0))-MAX(Y14,TIME(0,0,0)))*24)),"") -> 0 | AF14: 0.33333333 | AG14: 0.66666667 | AH14: =IFERROR(IF(OR(AF14="",AG14=""),"",IF($C14="평일",MIN(8,MAX(0,(AG14-AF14)*24-'1.설정(통합)'!$F$14)),0)),"") -> 0 | AI14: =IFERROR(IF(OR(AF14="",AG14="",$C14="휴일"),"",IF((AG14-AF14)*24-'1.설정(통합)'!$F$14>8,(AG14-AF14)*24-'1.설정(통합)'!$F$14-8,0)),"") | AJ14: =IFERROR(IF(OR(AF14="",AG14="",$C14="평일"),"",MIN(8,MAX(0,(AG14-AF14)*24-'1.설정(통합)'!$F$14))),"") -> 7 | AK14: =IFERROR(IF(OR(AF14="",AG14="",$C14="평일"),"",IF((AG14-AF14)*24-'1.설정(통합)'!$F$14>8,(AG14-AF14)*24-'1.설정(통합)'!$F$14-8,0)),"") -> 0 | AL14: =IFERROR(IF(OR(AF14="",AG14=""),"",MAX(0,(MIN(AG14,TIME(24,0,0)+TIME(6,0,0))-MAX(AF14,TIME(22,0,0)))*24)+MAX(0,(MIN(AG14,TIME(6,0,0))-MAX(AF14,TIME(0,0,0)))*24)),"") -> 0
A15: =IFERROR(IF(DAY(DATE(2000+$F$1,$H$1+1,0))<12,"",DATE(2000+$F$1,$H$1,12)),"") -> 46124 | B15: =IF(A15="","",CHOOSE(WEEKDAY(A15),"일","월","화","수","목","금","토")) -> 일 | C15: =IF(A15="","",IF(OR(WEEKDAY(A15,2)>5,COUNTIF('2.공휴일리스트'!$A$2:$A$1000,A15)>0),"휴일","평일")) -> 휴일 | F15: =IFERROR(IF(OR(D15="",E15=""),"",IF($C15="평일",MIN(8,MAX(0,(E15-D15)*24-'1.설정(통합)'!$B$14)),0)),"") | G15: =IFERROR(IF(OR(D15="",E15="",$C15="휴일"),"",IF((E15-D15)*24-'1.설정(통합)'!$B$14>8,(E15-D15)*24-'1.설정(통합)'!$B$14-8,0)),"") | H15: =IFERROR(IF(OR(D15="",E15="",$C15="평일"),"",MIN(8,MAX(0,(E15-D15)*24-'1.설정(통합)'!$B$14))),"") | I15: =IFERROR(IF(OR(D15="",E15="",$C15="평일"),"",IF((E15-D15)*24-'1.설정(통합)'!$B$14>8,(E15-D15)*24-'1.설정(통합)'!$B$14-8,0)),"") | J15: =IFERROR(IF(OR(D15="",E15=""),"",MAX(0,(MIN(E15,TIME(24,0,0)+TIME(6,0,0))-MAX(D15,TIME(22,0,0)))*24)+MAX(0,(MIN(E15,TIME(6,0,0))-MAX(D15,TIME(0,0,0)))*24)),"") | K15: 0.33333333 | L15: 0.64583333 | M15: =IFERROR(IF(OR(K15="",L15=""),"",IF($C15="평일",MIN(8,MAX(0,(L15-K15)*24-'1.설정(통합)'!$C$14)),0)),"") -> 0 | N15: =IFERROR(IF(OR(K15="",L15="",$C15="휴일"),"",IF((L15-K15)*24-'1.설정(통합)'!$C$14>8,(L15-K15)*24-'1.설정(통합)'!$C$14-8,0)),"") | O15: =IFERROR(IF(OR(K15="",L15="",$C15="평일"),"",MIN(8,MAX(0,(L15-K15)*24-'1.설정(통합)'!$C$14))),"") -> 6.5 | P15: =IFERROR(IF(OR(K15="",L15="",$C15="평일"),"",IF((L15-K15)*24-'1.설정(통합)'!$C$14>8,(L15-K15)*24-'1.설정(통합)'!$C$14-8,0)),"") -> 0 | Q15: =IFERROR(IF(OR(K15="",L15=""),"",MAX(0,(MIN(L15,TIME(24,0,0)+TIME(6,0,0))-MAX(K15,TIME(22,0,0)))*24)+MAX(0,(MIN(L15,TIME(6,0,0))-MAX(K15,TIME(0,0,0)))*24)),"") -> 0 | R15: 0.33333333 | S15: 0.64583333 | T15: =IFERROR(IF(OR(R15="",S15=""),"",IF($C15="평일",MIN(8,MAX(0,(S15-R15)*24-'1.설정(통합)'!$D$14)),0)),"") -> 0 | U15: =IFERROR(IF(OR(R15="",S15="",$C15="휴일"),"",IF((S15-R15)*24-'1.설정(통합)'!$D$14>8,(S15-R15)*24-'1.설정(통합)'!$D$14-8,0)),"") | V15: =IFERROR(IF(OR(R15="",S15="",$C15="평일"),"",MIN(8,MAX(0,(S15-R15)*24-'1.설정(통합)'!$D$14))),"") -> 6.5 | W15: =IFERROR(IF(OR(R15="",S15="",$C15="평일"),"",IF((S15-R15)*24-'1.설정(통합)'!$D$14>8,(S15-R15)*24-'1.설정(통합)'!$D$14-8,0)),"") -> 0 | X15: =IFERROR(IF(OR(R15="",S15=""),"",MAX(0,(MIN(S15,TIME(24,0,0)+TIME(6,0,0))-MAX(R15,TIME(22,0,0)))*24)+MAX(0,(MIN(S15,TIME(6,0,0))-MAX(R15,TIME(0,0,0)))*24)),"") -> 0 | Y15: 0.33333333 | Z15: 0.64583333 | AA15: =IFERROR(IF(OR(Y15="",Z15=""),"",IF($C15="평일",MIN(8,MAX(0,(Z15-Y15)*24-'1.설정(통합)'!$E$14)),0)),"") -> 0 | AB15: =IFERROR(IF(OR(Y15="",Z15="",$C15="휴일"),"",IF((Z15-Y15)*24-'1.설정(통합)'!$E$14>8,(Z15-Y15)*24-'1.설정(통합)'!$E$14-8,0)),"") | AC15: =IFERROR(IF(OR(Y15="",Z15="",$C15="평일"),"",MIN(8,MAX(0,(Z15-Y15)*24-'1.설정(통합)'!$E$14))),"") -> 6.5 | AD15: =IFERROR(IF(OR(Y15="",Z15="",$C15="평일"),"",IF((Z15-Y15)*24-'1.설정(통합)'!$E$14>8,(Z15-Y15)*24-'1.설정(통합)'!$E$14-8,0)),"") -> 0 | AE15: =IFERROR(IF(OR(Y15="",Z15=""),"",MAX(0,(MIN(Z15,TIME(24,0,0)+TIME(6,0,0))-MAX(Y15,TIME(22,0,0)))*24)+MAX(0,(MIN(Z15,TIME(6,0,0))-MAX(Y15,TIME(0,0,0)))*24)),"") -> 0 | AF15: 0.33333333 | AG15: 0.64583333 | AH15: =IFERROR(IF(OR(AF15="",AG15=""),"",IF($C15="평일",MIN(8,MAX(0,(AG15-AF15)*24-'1.설정(통합)'!$F$14)),0)),"") -> 0 | AI15: =IFERROR(IF(OR(AF15="",AG15="",$C15="휴일"),"",IF((AG15-AF15)*24-'1.설정(통합)'!$F$14>8,(AG15-AF15)*24-'1.설정(통합)'!$F$14-8,0)),"") | AJ15: =IFERROR(IF(OR(AF15="",AG15="",$C15="평일"),"",MIN(8,MAX(0,(AG15-AF15)*24-'1.설정(통합)'!$F$14))),"") -> 6.5 | AK15: =IFERROR(IF(OR(AF15="",AG15="",$C15="평일"),"",IF((AG15-AF15)*24-'1.설정(통합)'!$F$14>8,(AG15-AF15)*24-'1.설정(통합)'!$F$14-8,0)),"") -> 0 | AL15: =IFERROR(IF(OR(AF15="",AG15=""),"",MAX(0,(MIN(AG15,TIME(24,0,0)+TIME(6,0,0))-MAX(AF15,TIME(22,0,0)))*24)+MAX(0,(MIN(AG15,TIME(6,0,0))-MAX(AF15,TIME(0,0,0)))*24)),"") -> 0
A16: =IFERROR(IF(DAY(DATE(2000+$F$1,$H$1+1,0))<13,"",DATE(2000+$F$1,$H$1,13)),"") -> 46125 | B16: =IF(A16="","",CHOOSE(WEEKDAY(A16),"일","월","화","수","목","금","토")) -> 월 | C16: =IF(A16="","",IF(OR(WEEKDAY(A16,2)>5,COUNTIF('2.공휴일리스트'!$A$2:$A$1000,A16)>0),"휴일","평일")) -> 평일 | F16: =IFERROR(IF(OR(D16="",E16=""),"",IF($C16="평일",MIN(8,MAX(0,(E16-D16)*24-'1.설정(통합)'!$B$14)),0)),"") | G16: =IFERROR(IF(OR(D16="",E16="",$C16="휴일"),"",IF((E16-D16)*24-'1.설정(통합)'!$B$14>8,(E16-D16)*24-'1.설정(통합)'!$B$14-8,0)),"") | H16: =IFERROR(IF(OR(D16="",E16="",$C16="평일"),"",MIN(8,MAX(0,(E16-D16)*24-'1.설정(통합)'!$B$14))),"") | I16: =IFERROR(IF(OR(D16="",E16="",$C16="평일"),"",IF((E16-D16)*24-'1.설정(통합)'!$B$14>8,(E16-D16)*24-'1.설정(통합)'!$B$14-8,0)),"") | J16: =IFERROR(IF(OR(D16="",E16=""),"",MAX(0,(MIN(E16,TIME(24,0,0)+TIME(6,0,0))-MAX(D16,TIME(22,0,0)))*24)+MAX(0,(MIN(E16,TIME(6,0,0))-MAX(D16,TIME(0,0,0)))*24)),"") | K16: 0.33333333 | L16: 0.70833333 | M16: =IFERROR(IF(OR(K16="",L16=""),"",IF($C16="평일",MIN(8,MAX(0,(L16-K16)*24-'1.설정(통합)'!$C$14)),0)),"") -> 8 | N16: =IFERROR(IF(OR(K16="",L16="",$C16="휴일"),"",IF((L16-K16)*24-'1.설정(통합)'!$C$14>8,(L16-K16)*24-'1.설정(통합)'!$C$14-8,0)),"") -> 0 | O16: =IFERROR(IF(OR(K16="",L16="",$C16="평일"),"",MIN(8,MAX(0,(L16-K16)*24-'1.설정(통합)'!$C$14))),"") | P16: =IFERROR(IF(OR(K16="",L16="",$C16="평일"),"",IF((L16-K16)*24-'1.설정(통합)'!$C$14>8,(L16-K16)*24-'1.설정(통합)'!$C$14-8,0)),"") | Q16: =IFERROR(IF(OR(K16="",L16=""),"",MAX(0,(MIN(L16,TIME(24,0,0)+TIME(6,0,0))-MAX(K16,TIME(22,0,0)))*24)+MAX(0,(MIN(L16,TIME(6,0,0))-MAX(K16,TIME(0,0,0)))*24)),"") -> 0 | R16: 0.33333333 | S16: 0.70833333 | T16: =IFERROR(IF(OR(R16="",S16=""),"",IF($C16="평일",MIN(8,MAX(0,(S16-R16)*24-'1.설정(통합)'!$D$14)),0)),"") -> 8 | U16: =IFERROR(IF(OR(R16="",S16="",$C16="휴일"),"",IF((S16-R16)*24-'1.설정(통합)'!$D$14>8,(S16-R16)*24-'1.설정(통합)'!$D$14-8,0)),"") -> 0 | V16: =IFERROR(IF(OR(R16="",S16="",$C16="평일"),"",MIN(8,MAX(0,(S16-R16)*24-'1.설정(통합)'!$D$14))),"") | W16: =IFERROR(IF(OR(R16="",S16="",$C16="평일"),"",IF((S16-R16)*24-'1.설정(통합)'!$D$14>8,(S16-R16)*24-'1.설정(통합)'!$D$14-8,0)),"") | X16: =IFERROR(IF(OR(R16="",S16=""),"",MAX(0,(MIN(S16,TIME(24,0,0)+TIME(6,0,0))-MAX(R16,TIME(22,0,0)))*24)+MAX(0,(MIN(S16,TIME(6,0,0))-MAX(R16,TIME(0,0,0)))*24)),"") -> 0 | Y16: 0.33333333 | Z16: 0.8125 | AA16: =IFERROR(IF(OR(Y16="",Z16=""),"",IF($C16="평일",MIN(8,MAX(0,(Z16-Y16)*24-'1.설정(통합)'!$E$14)),0)),"") -> 8 | AB16: =IFERROR(IF(OR(Y16="",Z16="",$C16="휴일"),"",IF((Z16-Y16)*24-'1.설정(통합)'!$E$14>8,(Z16-Y16)*24-'1.설정(통합)'!$E$14-8,0)),"") -> 2.5 | AC16: =IFERROR(IF(OR(Y16="",Z16="",$C16="평일"),"",MIN(8,MAX(0,(Z16-Y16)*24-'1.설정(통합)'!$E$14))),"") | AD16: =IFERROR(IF(OR(Y16="",Z16="",$C16="평일"),"",IF((Z16-Y16)*24-'1.설정(통합)'!$E$14>8,(Z16-Y16)*24-'1.설정(통합)'!$E$14-8,0)),"") | AE16: =IFERROR(IF(OR(Y16="",Z16=""),"",MAX(0,(MIN(Z16,TIME(24,0,0)+TIME(6,0,0))-MAX(Y16,TIME(22,0,0)))*24)+MAX(0,(MIN(Z16,TIME(6,0,0))-MAX(Y16,TIME(0,0,0)))*24)),"") -> 0 | AF16: 0.33333333 | AG16: 0.70833333 | AH16: =IFERROR(IF(OR(AF16="",AG16=""),"",IF($C16="평일",MIN(8,MAX(0,(AG16-AF16)*24-'1.설정(통합)'!$F$14)),0)),"") -> 8 | AI16: =IFERROR(IF(OR(AF16="",AG16="",$C16="휴일"),"",IF((AG16-AF16)*24-'1.설정(통합)'!$F$14>8,(AG16-AF16)*24-'1.설정(통합)'!$F$14-8,0)),"") -> 0 | AJ16: =IFERROR(IF(OR(AF16="",AG16="",$C16="평일"),"",MIN(8,MAX(0,(AG16-AF16)*24-'1.설정(통합)'!$F$14))),"") | AK16: =IFERROR(IF(OR(AF16="",AG16="",$C16="평일"),"",IF((AG16-AF16)*24-'1.설정(통합)'!$F$14>8,(AG16-AF16)*24-'1.설정(통합)'!$F$14-8,0)),"") | AL16: =IFERROR(IF(OR(AF16="",AG16=""),"",MAX(0,(MIN(AG16,TIME(24,0,0)+TIME(6,0,0))-MAX(AF16,TIME(22,0,0)))*24)+MAX(0,(MIN(AG16,TIME(6,0,0))-MAX(AF16,TIME(0,0,0)))*24)),"") -> 0
A17: =IFERROR(IF(DAY(DATE(2000+$F$1,$H$1+1,0))<14,"",DATE(2000+$F$1,$H$1,14)),"") -> 46126 | B17: =IF(A17="","",CHOOSE(WEEKDAY(A17),"일","월","화","수","목","금","토")) -> 화 | C17: =IF(A17="","",IF(OR(WEEKDAY(A17,2)>5,COUNTIF('2.공휴일리스트'!$A$2:$A$1000,A17)>0),"휴일","평일")) -> 평일 | F17: =IFERROR(IF(OR(D17="",E17=""),"",IF($C17="평일",MIN(8,MAX(0,(E17-D17)*24-'1.설정(통합)'!$B$14)),0)),"") | G17: =IFERROR(IF(OR(D17="",E17="",$C17="휴일"),"",IF((E17-D17)*24-'1.설정(통합)'!$B$14>8,(E17-D17)*24-'1.설정(통합)'!$B$14-8,0)),"") | H17: =IFERROR(IF(OR(D17="",E17="",$C17="평일"),"",MIN(8,MAX(0,(E17-D17)*24-'1.설정(통합)'!$B$14))),"") | I17: =IFERROR(IF(OR(D17="",E17="",$C17="평일"),"",IF((E17-D17)*24-'1.설정(통합)'!$B$14>8,(E17-D17)*24-'1.설정(통합)'!$B$14-8,0)),"") | J17: =IFERROR(IF(OR(D17="",E17=""),"",MAX(0,(MIN(E17,TIME(24,0,0)+TIME(6,0,0))-MAX(D17,TIME(22,0,0)))*24)+MAX(0,(MIN(E17,TIME(6,0,0))-MAX(D17,TIME(0,0,0)))*24)),"") | K17: 0.33333333 | L17: 0.70833333 | M17: =IFERROR(IF(OR(K17="",L17=""),"",IF($C17="평일",MIN(8,MAX(0,(L17-K17)*24-'1.설정(통합)'!$C$14)),0)),"") -> 8 | N17: =IFERROR(IF(OR(K17="",L17="",$C17="휴일"),"",IF((L17-K17)*24-'1.설정(통합)'!$C$14>8,(L17-K17)*24-'1.설정(통합)'!$C$14-8,0)),"") -> 0 | O17: =IFERROR(IF(OR(K17="",L17="",$C17="평일"),"",MIN(8,MAX(0,(L17-K17)*24-'1.설정(통합)'!$C$14))),"") | P17: =IFERROR(IF(OR(K17="",L17="",$C17="평일"),"",IF((L17-K17)*24-'1.설정(통합)'!$C$14>8,(L17-K17)*24-'1.설정(통합)'!$C$14-8,0)),"") | Q17: =IFERROR(IF(OR(K17="",L17=""),"",MAX(0,(MIN(L17,TIME(24,0,0)+TIME(6,0,0))-MAX(K17,TIME(22,0,0)))*24)+MAX(0,(MIN(L17,TIME(6,0,0))-MAX(K17,TIME(0,0,0)))*24)),"") -> 0 | R17: 0.33333333 | S17: 0.70833333 | T17: =IFERROR(IF(OR(R17="",S17=""),"",IF($C17="평일",MIN(8,MAX(0,(S17-R17)*24-'1.설정(통합)'!$D$14)),0)),"") -> 8 | U17: =IFERROR(IF(OR(R17="",S17="",$C17="휴일"),"",IF((S17-R17)*24-'1.설정(통합)'!$D$14>8,(S17-R17)*24-'1.설정(통합)'!$D$14-8,0)),"") -> 0 | V17: =IFERROR(IF(OR(R17="",S17="",$C17="평일"),"",MIN(8,MAX(0,(S17-R17)*24-'1.설정(통합)'!$D$14))),"") | W17: =IFERROR(IF(OR(R17="",S17="",$C17="평일"),"",IF((S17-R17)*24-'1.설정(통합)'!$D$14>8,(S17-R17)*24-'1.설정(통합)'!$D$14-8,0)),"") | X17: =IFERROR(IF(OR(R17="",S17=""),"",MAX(0,(MIN(S17,TIME(24,0,0)+TIME(6,0,0))-MAX(R17,TIME(22,0,0)))*24)+MAX(0,(MIN(S17,TIME(6,0,0))-MAX(R17,TIME(0,0,0)))*24)),"") -> 0 | Y17: 0.33333333 | Z17: 0.8125 | AA17: =IFERROR(IF(OR(Y17="",Z17=""),"",IF($C17="평일",MIN(8,MAX(0,(Z17-Y17)*24-'1.설정(통합)'!$E$14)),0)),"") -> 8 | AB17: =IFERROR(IF(OR(Y17="",Z17="",$C17="휴일"),"",IF((Z17-Y17)*24-'1.설정(통합)'!$E$14>8,(Z17-Y17)*24-'1.설정(통합)'!$E$14-8,0)),"") -> 2.5 | AC17: =IFERROR(IF(OR(Y17="",Z17="",$C17="평일"),"",MIN(8,MAX(0,(Z17-Y17)*24-'1.설정(통합)'!$E$14))),"") | AD17: =IFERROR(IF(OR(Y17="",Z17="",$C17="평일"),"",IF((Z17-Y17)*24-'1.설정(통합)'!$E$14>8,(Z17-Y17)*24-'1.설정(통합)'!$E$14-8,0)),"") | AE17: =IFERROR(IF(OR(Y17="",Z17=""),"",MAX(0,(MIN(Z17,TIME(24,0,0)+TIME(6,0,0))-MAX(Y17,TIME(22,0,0)))*24)+MAX(0,(MIN(Z17,TIME(6,0,0))-MAX(Y17,TIME(0,0,0)))*24)),"") -> 0 | AF17: 0.33333333 | AG17: 0.8125 | AH17: =IFERROR(IF(OR(AF17="",AG17=""),"",IF($C17="평일",MIN(8,MAX(0,(AG17-AF17)*24-'1.설정(통합)'!$F$14)),0)),"") -> 8 | AI17: =IFERROR(IF(OR(AF17="",AG17="",$C17="휴일"),"",IF((AG17-AF17)*24-'1.설정(통합)'!$F$14>8,(AG17-AF17)*24-'1.설정(통합)'!$F$14-8,0)),"") -> 2.5 | AJ17: =IFERROR(IF(OR(AF17="",AG17="",$C17="평일"),"",MIN(8,MAX(0,(AG17-AF17)*24-'1.설정(통합)'!$F$14))),"") | AK17: =IFERROR(IF(OR(AF17="",AG17="",$C17="평일"),"",IF((AG17-AF17)*24-'1.설정(통합)'!$F$14>8,(AG17-AF17)*24-'1.설정(통합)'!$F$14-8,0)),"") | AL17: =IFERROR(IF(OR(AF17="",AG17=""),"",MAX(0,(MIN(AG17,TIME(24,0,0)+TIME(6,0,0))-MAX(AF17,TIME(22,0,0)))*24)+MAX(0,(MIN(AG17,TIME(6,0,0))-MAX(AF17,TIME(0,0,0)))*24)),"") -> 0
A18: =IFERROR(IF(DAY(DATE(2000+$F$1,$H$1+1,0))<15,"",DATE(2000+$F$1,$H$1,15)),"") -> 46127 | B18: =IF(A18="","",CHOOSE(WEEKDAY(A18),"일","월","화","수","목","금","토")) -> 수 | C18: =IF(A18="","",IF(OR(WEEKDAY(A18,2)>5,COUNTIF('2.공휴일리스트'!$A$2:$A$1000,A18)>0),"휴일","평일")) -> 평일 | D18: 0.33333333 | E18: 0.70833333 | F18: =IFERROR(IF(OR(D18="",E18=""),"",IF($C18="평일",MIN(8,MAX(0,(E18-D18)*24-'1.설정(통합)'!$B$14)),0)),"") -> 8 | G18: =IFERROR(IF(OR(D18="",E18="",$C18="휴일"),"",IF((E18-D18)*24-'1.설정(통합)'!$B$14>8,(E18-D18)*24-'1.설정(통합)'!$B$14-8,0)),"") -> 0 | H18: =IFERROR(IF(OR(D18="",E18="",$C18="평일"),"",MIN(8,MAX(0,(E18-D18)*24-'1.설정(통합)'!$B$14))),"") | I18: =IFERROR(IF(OR(D18="",E18="",$C18="평일"),"",IF((E18-D18)*24-'1.설정(통합)'!$B$14>8,(E18-D18)*24-'1.설정(통합)'!$B$14-8,0)),"") | J18: =IFERROR(IF(OR(D18="",E18=""),"",MAX(0,(MIN(E18,TIME(24,0,0)+TIME(6,0,0))-MAX(D18,TIME(22,0,0)))*24)+MAX(0,(MIN(E18,TIME(6,0,0))-MAX(D18,TIME(0,0,0)))*24)),"") -> 0 | K18: 0.33333333 | L18: 0.70833333 | M18: =IFERROR(IF(OR(K18="",L18=""),"",IF($C18="평일",MIN(8,MAX(0,(L18-K18)*24-'1.설정(통합)'!$C$14)),0)),"") -> 8 | N18: =IFERROR(IF(OR(K18="",L18="",$C18="휴일"),"",IF((L18-K18)*24-'1.설정(통합)'!$C$14>8,(L18-K18)*24-'1.설정(통합)'!$C$14-8,0)),"") -> 0 | O18: =IFERROR(IF(OR(K18="",L18="",$C18="평일"),"",MIN(8,MAX(0,(L18-K18)*24-'1.설정(통합)'!$C$14))),"") | P18: =IFERROR(IF(OR(K18="",L18="",$C18="평일"),"",IF((L18-K18)*24-'1.설정(통합)'!$C$14>8,(L18-K18)*24-'1.설정(통합)'!$C$14-8,0)),"") | Q18: =IFERROR(IF(OR(K18="",L18=""),"",MAX(0,(MIN(L18,TIME(24,0,0)+TIME(6,0,0))-MAX(K18,TIME(22,0,0)))*24)+MAX(0,(MIN(L18,TIME(6,0,0))-MAX(K18,TIME(0,0,0)))*24)),"") -> 0 | R18: 0.33333333 | S18: 0.70833333 | T18: =IFERROR(IF(OR(R18="",S18=""),"",IF($C18="평일",MIN(8,MAX(0,(S18-R18)*24-'1.설정(통합)'!$D$14)),0)),"") -> 8 | U18: =IFERROR(IF(OR(R18="",S18="",$C18="휴일"),"",IF((S18-R18)*24-'1.설정(통합)'!$D$14>8,(S18-R18)*24-'1.설정(통합)'!$D$14-8,0)),"") -> 0 | V18: =IFERROR(IF(OR(R18="",S18="",$C18="평일"),"",MIN(8,MAX(0,(S18-R18)*24-'1.설정(통합)'!$D$14))),"") | W18: =IFERROR(IF(OR(R18="",S18="",$C18="평일"),"",IF((S18-R18)*24-'1.설정(통합)'!$D$14>8,(S18-R18)*24-'1.설정(통합)'!$D$14-8,0)),"") | X18: =IFERROR(IF(OR(R18="",S18=""),"",MAX(0,(MIN(S18,TIME(24,0,0)+TIME(6,0,0))-MAX(R18,TIME(22,0,0)))*24)+MAX(0,(MIN(S18,TIME(6,0,0))-MAX(R18,TIME(0,0,0)))*24)),"") -> 0 | Y18: 0.33333333 | Z18: 0.8125 | AA18: =IFERROR(IF(OR(Y18="",Z18=""),"",IF($C18="평일",MIN(8,MAX(0,(Z18-Y18)*24-'1.설정(통합)'!$E$14)),0)),"") -> 8 | AB18: =IFERROR(IF(OR(Y18="",Z18="",$C18="휴일"),"",IF((Z18-Y18)*24-'1.설정(통합)'!$E$14>8,(Z18-Y18)*24-'1.설정(통합)'!$E$14-8,0)),"") -> 2.5 | AC18: =IFERROR(IF(OR(Y18="",Z18="",$C18="평일"),"",MIN(8,MAX(0,(Z18-Y18)*24-'1.설정(통합)'!$E$14))),"") | AD18: =IFERROR(IF(OR(Y18="",Z18="",$C18="평일"),"",IF((Z18-Y18)*24-'1.설정(통합)'!$E$14>8,(Z18-Y18)*24-'1.설정(통합)'!$E$14-8,0)),"") | AE18: =IFERROR(IF(OR(Y18="",Z18=""),"",MAX(0,(MIN(Z18,TIME(24,0,0)+TIME(6,0,0))-MAX(Y18,TIME(22,0,0)))*24)+MAX(0,(MIN(Z18,TIME(6,0,0))-MAX(Y18,TIME(0,0,0)))*24)),"") -> 0 | AF18: 0.33333333 | AG18: 0.70833333 | AH18: =IFERROR(IF(OR(AF18="",AG18=""),"",IF($C18="평일",MIN(8,MAX(0,(AG18-AF18)*24-'1.설정(통합)'!$F$14)),0)),"") -> 8 | AI18: =IFERROR(IF(OR(AF18="",AG18="",$C18="휴일"),"",IF((AG18-AF18)*24-'1.설정(통합)'!$F$14>8,(AG18-AF18)*24-'1.설정(통합)'!$F$14-8,0)),"") -> 0 | AJ18: =IFERROR(IF(OR(AF18="",AG18="",$C18="평일"),"",MIN(8,MAX(0,(AG18-AF18)*24-'1.설정(통합)'!$F$14))),"") | AK18: =IFERROR(IF(OR(AF18="",AG18="",$C18="평일"),"",IF((AG18-AF18)*24-'1.설정(통합)'!$F$14>8,(AG18-AF18)*24-'1.설정(통합)'!$F$14-8,0)),"") | AL18: =IFERROR(IF(OR(AF18="",AG18=""),"",MAX(0,(MIN(AG18,TIME(24,0,0)+TIME(6,0,0))-MAX(AF18,TIME(22,0,0)))*24)+MAX(0,(MIN(AG18,TIME(6,0,0))-MAX(AF18,TIME(0,0,0)))*24)),"") -> 0
A19: =IFERROR(IF(DAY(DATE(2000+$F$1,$H$1+1,0))<16,"",DATE(2000+$F$1,$H$1,16)),"") -> 46128 | B19: =IF(A19="","",CHOOSE(WEEKDAY(A19),"일","월","화","수","목","금","토")) -> 목 | C19: =IF(A19="","",IF(OR(WEEKDAY(A19,2)>5,COUNTIF('2.공휴일리스트'!$A$2:$A$1000,A19)>0),"휴일","평일")) -> 평일 | D19: 0.33333333 | E19: 0.70833333 | F19: =IFERROR(IF(OR(D19="",E19=""),"",IF($C19="평일",MIN(8,MAX(0,(E19-D19)*24-'1.설정(통합)'!$B$14)),0)),"") -> 8 | G19: =IFERROR(IF(OR(D19="",E19="",$C19="휴일"),"",IF((E19-D19)*24-'1.설정(통합)'!$B$14>8,(E19-D19)*24-'1.설정(통합)'!$B$14-8,0)),"") -> 0 | H19: =IFERROR(IF(OR(D19="",E19="",$C19="평일"),"",MIN(8,MAX(0,(E19-D19)*24-'1.설정(통합)'!$B$14))),"") | I19: =IFERROR(IF(OR(D19="",E19="",$C19="평일"),"",IF((E19-D19)*24-'1.설정(통합)'!$B$14>8,(E19-D19)*24-'1.설정(통합)'!$B$14-8,0)),"") | J19: =IFERROR(IF(OR(D19="",E19=""),"",MAX(0,(MIN(E19,TIME(24,0,0)+TIME(6,0,0))-MAX(D19,TIME(22,0,0)))*24)+MAX(0,(MIN(E19,TIME(6,0,0))-MAX(D19,TIME(0,0,0)))*24)),"") -> 0 | K19: 0.33333333 | L19: 0.70833333 | M19: =IFERROR(IF(OR(K19="",L19=""),"",IF($C19="평일",MIN(8,MAX(0,(L19-K19)*24-'1.설정(통합)'!$C$14)),0)),"") -> 8 | N19: =IFERROR(IF(OR(K19="",L19="",$C19="휴일"),"",IF((L19-K19)*24-'1.설정(통합)'!$C$14>8,(L19-K19)*24-'1.설정(통합)'!$C$14-8,0)),"") -> 0 | O19: =IFERROR(IF(OR(K19="",L19="",$C19="평일"),"",MIN(8,MAX(0,(L19-K19)*24-'1.설정(통합)'!$C$14))),"") | P19: =IFERROR(IF(OR(K19="",L19="",$C19="평일"),"",IF((L19-K19)*24-'1.설정(통합)'!$C$14>8,(L19-K19)*24-'1.설정(통합)'!$C$14-8,0)),"") | Q19: =IFERROR(IF(OR(K19="",L19=""),"",MAX(0,(MIN(L19,TIME(24,0,0)+TIME(6,0,0))-MAX(K19,TIME(22,0,0)))*24)+MAX(0,(MIN(L19,TIME(6,0,0))-MAX(K19,TIME(0,0,0)))*24)),"") -> 0 | R19: 0.33333333 | S19: 0.70833333 | T19: =IFERROR(IF(OR(R19="",S19=""),"",IF($C19="평일",MIN(8,MAX(0,(S19-R19)*24-'1.설정(통합)'!$D$14)),0)),"") -> 8 | U19: =IFERROR(IF(OR(R19="",S19="",$C19="휴일"),"",IF((S19-R19)*24-'1.설정(통합)'!$D$14>8,(S19-R19)*24-'1.설정(통합)'!$D$14-8,0)),"") -> 0 | V19: =IFERROR(IF(OR(R19="",S19="",$C19="평일"),"",MIN(8,MAX(0,(S19-R19)*24-'1.설정(통합)'!$D$14))),"") | W19: =IFERROR(IF(OR(R19="",S19="",$C19="평일"),"",IF((S19-R19)*24-'1.설정(통합)'!$D$14>8,(S19-R19)*24-'1.설정(통합)'!$D$14-8,0)),"") | X19: =IFERROR(IF(OR(R19="",S19=""),"",MAX(0,(MIN(S19,TIME(24,0,0)+TIME(6,0,0))-MAX(R19,TIME(22,0,0)))*24)+MAX(0,(MIN(S19,TIME(6,0,0))-MAX(R19,TIME(0,0,0)))*24)),"") -> 0 | Y19: 0.33333333 | Z19: 0.70833333 | AA19: =IFERROR(IF(OR(Y19="",Z19=""),"",IF($C19="평일",MIN(8,MAX(0,(Z19-Y19)*24-'1.설정(통합)'!$E$14)),0)),"") -> 8 | AB19: =IFERROR(IF(OR(Y19="",Z19="",$C19="휴일"),"",IF((Z19-Y19)*24-'1.설정(통합)'!$E$14>8,(Z19-Y19)*24-'1.설정(통합)'!$E$14-8,0)),"") -> 0 | AC19: =IFERROR(IF(OR(Y19="",Z19="",$C19="평일"),"",MIN(8,MAX(0,(Z19-Y19)*24-'1.설정(통합)'!$E$14))),"") | AD19: =IFERROR(IF(OR(Y19="",Z19="",$C19="평일"),"",IF((Z19-Y19)*24-'1.설정(통합)'!$E$14>8,(Z19-Y19)*24-'1.설정(통합)'!$E$14-8,0)),"") | AE19: =IFERROR(IF(OR(Y19="",Z19=""),"",MAX(0,(MIN(Z19,TIME(24,0,0)+TIME(6,0,0))-MAX(Y19,TIME(22,0,0)))*24)+MAX(0,(MIN(Z19,TIME(6,0,0))-MAX(Y19,TIME(0,0,0)))*24)),"") -> 0 | AF19: 0.33333333 | AG19: 0.70833333 | AH19: =IFERROR(IF(OR(AF19="",AG19=""),"",IF($C19="평일",MIN(8,MAX(0,(AG19-AF19)*24-'1.설정(통합)'!$F$14)),0)),"") -> 8 | AI19: =IFERROR(IF(OR(AF19="",AG19="",$C19="휴일"),"",IF((AG19-AF19)*24-'1.설정(통합)'!$F$14>8,(AG19-AF19)*24-'1.설정(통합)'!$F$14-8,0)),"") -> 0 | AJ19: =IFERROR(IF(OR(AF19="",AG19="",$C19="평일"),"",MIN(8,MAX(0,(AG19-AF19)*24-'1.설정(통합)'!$F$14))),"") | AK19: =IFERROR(IF(OR(AF19="",AG19="",$C19="평일"),"",IF((AG19-AF19)*24-'1.설정(통합)'!$F$14>8,(AG19-AF19)*24-'1.설정(통합)'!$F$14-8,0)),"") | AL19: =IFERROR(IF(OR(AF19="",AG19=""),"",MAX(0,(MIN(AG19,TIME(24,0,0)+TIME(6,0,0))-MAX(AF19,TIME(22,0,0)))*24)+MAX(0,(MIN(AG19,TIME(6,0,0))-MAX(AF19,TIME(0,0,0)))*24)),"") -> 0
