Workbook

Sheet 2026년5월전체
K1: =AU20*209 -> 2156880 | S1: 2026 | V1: 5 | X1: 노무대장
C2: ▣ 씨엠(CM)건설 | K2: =K1-AW20 -> 1956880 | N2: ="지급일 : "&TEXT(DATE($S$1,$V$1+1,15),"yyyy년 m월 d일") -> 지급일 : 2026년 6월 15일 | AV2: 지 급 내 역 | BB2: 공 제 내 역 | BH2: 실지급액 | BI2: 비고
A3: NO | B3: 사 번 | C3: 이름 | D3: 영문이름 | E3: 고용 형태 | F3: 주민등록번호 | G3: 입사입 | H3: 퇴사일 | I3: 계좌번호 | J3: 연락처 | K3: 주 소 | L3: 직무 | M3: 구분 | N3: =DATE($S$1,$V$1,1) -> 46143 | O3: =IF(N3="","",IF(MONTH(N3+1)=$V$1,N3+1,"")) -> 46144 | P3: =IF(O3="","",IF(MONTH(O3+1)=$V$1,O3+1,"")) -> 46145 | Q3: =IF(P3="","",IF(MONTH(P3+1)=$V$1,P3+1,"")) -> 46146 | R3: =IF(Q3="","",IF(MONTH(Q3+1)=$V$1,Q3+1,"")) -> 46147 | S3: =IF(R3="","",IF(MONTH(R3+1)=$V$1,R3+1,"")) -> 46148 | T3: =IF(S3="","",IF(MONTH(S3+1)=$V$1,S3+1,"")) -> 46149 | U3: =IF(T3="","",IF(MONTH(T3+1)=$V$1,T3+1,"")) -> 46150 | V3: =IF(U3="","",IF(MONTH(U3+1)=$V$1,U3+1,"")) -> 46151 | ... AR3: =IF(AQ3="","",IF(MONTH(AQ3+1)=$V$1,AQ3+1,"")) -> 46173 | AS3: 일수 | AT3: 형태 | AU3: 단가 | AV3: 기본급 | AW3: 식대 | AX3: 자가운전 | AY3: 통신비 | AZ3: 직책수당 | BA3: 합 계 | BB3: 국민연금 | BC3: 건강보험 | BD3: 장기요양보험 | BE3: 숙소료 | BF3: 기타 | BG3: 합계
AV4: 연장수당 | AW4: 휴일수당 | AX4: 휴일연장 | AY4: 심야수당 | AZ4: 기타 | BB4: 고용보험 | BC4: 소득세 | BD4: 지방소득세 | BE4: 가불
A5: 1 | B5: CM001 | C5: 문현준 | E5: 대표 | F5: 711111-1668118 | I5: 하나 518910657 09607 | J5: 010-5914-9246 | K5: 경북 경주 안강읍 피일길 86-17, 202동 505호(한동화성타운) | L5: 대표 | M5: 출근 | O5: 0.33333333 | P5: 0.33333333 | Q5: 0.33333333 | S5: 0.33333333 | T5: 0.33333333 | U5: 0.33333333 | V5: 0.33333333 | W5: 0.33333333 | X5: 0.33333333 | Y5: 0.33333333 | Z5: 0.33333333 | AS5: =SUMPRODUCT(--((N5:AR5<>"")+(N6:AR6<>"")>0)) -> 11 | AT5: =IF(OR(E5="일용",E5="사업"&CHAR(10)&"소득"),"일당",IF(E5="시급","시급",IF(E5="월급","월급",""))) | BA5: =SUM(AV5:AZ6) -> 0 | BG5: =SUM(BB5:BF6) -> 0 | BH5: =BA5-BG5 -> 0
M6: 퇴근 | O6: 0.66666667 | P6: 0.64583333 | Q6: 0.70833333 | S6: 0.70833333 | T6: 0.8125 | U6: 0.8125 | V6: 0.66666667 | W6: 0.64583333 | X6: 0.91666667 | Y6: 0.91666667 | Z6: 0.91666667
A7: =A5+1 -> 2 | B7: CM002 | C7: 정찬영 | E7: 월급 | F7: 700110-1452435 | G7: 45870 | I7: 국민 405-21-0147-271 | J7: 010-3421-2615 | K7: 서울 영등포구 도림로 313 건영 가동 708호 | L7: 관리 | M7: 출근 | O7: 0.33333333 | P7: 0.33333333 | Q7: 0.33333333 | R7: 0.33333333 | S7: 0.33333333 | T7: 0.33333333 | U7: 0.33333333 | X7: 0.33333333 | Y7: 0.33333333 | Z7: 0.33333333 | AS7: =SUMPRODUCT(--((N7:AR7<>"")+(N8:AR8<>"")>0)) -> 10 | AT7: =IF(OR(E7="일용",E7="사업"&CHAR(10)&"소득"),"일당",IF(E7="시급","시급",IF(E7="월급","월급",""))) -> 월급 | AU7: =ROUNDUP(BA7/209,-1) -> 24410 | AV7: 4600000 | AW7: 200000 | AX7: 200000 | AY7: 100000 | BA7: =SUM(AV7:AZ8) -> 5100000 | BG7: =SUM(BB7:BF8) -> 0 | BH7: =BA7-BG7 -> 5100000
M8: 퇴근 | O8: 0.66666667 | P8: 0.64583333 | Q8: 0.70833333 | R8: 0.66666667 | S8: 0.70833333 | T8: 0.70833333 | U8: 0.8125 | X8: 0.8125 | Y8: 0.8125 | Z8: 0.8125
M9: 연장
A10: =A7+1 -> 3 | B10: CM003 | C10: 박정선 | E10: 월급 | F10: 740205-2565919 | G10: 45870 | I10: 우체국 700591-02-214400 | J10: 010-5288-9246 | K10: 경북 경주시 안강읍 피일길 86-17, 203동 4층 402호 | L10: 관리 | M10: 출근 | Q10: 0.33333333 | S10: 0.33333333 | T10: 0.33333333 | U10: 0.33333333 | X10: 0.33333333 | Y10: 0.33333333 | Z10: 0.33333333 | AS10: =SUMPRODUCT(--((N10:AR10<>"")+(N11:AR11<>"")>0)) -> 7 | AT10: =IF(OR(E10="일용",E10="사업"&CHAR(10)&"소득"),"일당",IF(E10="시급","시급",IF(E10="월급","월급",""))) -> 월급 | AU10: =ROUNDUP(BA10/209,-1) -> 19140 | AV10: 3800000 | AW10: 200000 | BA10: =SUM(AV10:AZ11) -> 4000000 | BG10: =SUM(BB10:BF11) -> 0 | BH10: =BA10-BG10 -> 4000000
M11: 퇴근 | Q11: 0.70833333 | S11: 0.70833333 | T11: 0.70833333 | U11: 0.70833333 | X11: 0.70833333 | Y11: 0.70833333 | Z11: 0.70833333
A12: =A10+1 -> 4 | B12: CM004 | C12: 문지수 | E12: 월급 | F12: 040713-4785410 | G12: 45870 | I12: 신한 110-582-433226 | J12: 010-5344-9246 | K12: 경북 경주시 안강읍 피일길 86-17, 203동 4층 402호 | L12: 관리 | M12: 출근 | Q12: 0.33333333 | S12: 0.33333333 | T12: 0.33333333 | U12: 0.33333333 | X12: 0.33333333 | Y12: 0.33333333 | Z12: 0.33333333 | AS12: =SUMPRODUCT(--((N12:AR12<>"")+(N13:AR13<>"")>0)) -> 7 | AT12: =IF(OR(E12="일용",E12="사업"&CHAR(10)&"소득"),"일당",IF(E12="시급","시급",IF(E12="월급","월급",""))) -> 월급 | AU12: =ROUNDUP(BA12/209,-1) -> 14360 | AV12: 2800000 | AW12: 200000 | BA12: =SUM(AV12:AZ13) -> 3000000 | BG12: =SUM(BB12:BF13) -> 0 | BH12: =BA12-BG12 -> 3000000
M13: 퇴근 | Q13: 0.70833333 | S13: 0.70833333 | T13: 0.70833333 | U13: 0.70833333 | X13: 0.70833333 | Y13: 0.70833333 | Z13: 0.70833333
A14: =A12+1 -> 5 | B14: CM005 | C14: 김인진 | E14: 일용 | F14: 720313-1473617 | G14: 45870 | I14: 농협 217030-56-032198 | J14: 010-5536-1383 | K14: 충남 당진시 순성면 순성로 454, 2동 104호(세안근로자복지아파트) | L14: 용접 | M14: 출근 | O14: 0.33333333 | P14: 0.33333333 | Q14: 0.33333333 | R14: 0.33333333 | S14: 0.33333333 | T14: 0.33333333 | U14: 0.33333333 | V14: 0.33333333 | W14: 0.33333333 | X14: 0.33333333 | Y14: 0.33333333 | Z14: 0.33333333 | AS14: =SUMPRODUCT(--((N14:AR14<>"")+(N15:AR15<>"")>0)) -> 12 | AT14: =IF(OR(E14="일용",E14="사업"&CHAR(10)&"소득"),"일당",IF(E14="시급","시급",IF(E14="월급","월급",""))) -> 일당 | AU14: 160000 | AW14: 200000 | AX14: 200000 | BA14: =SUM(AV14:AZ15) -> 400000 | BG14: =SUM(BB14:BF15) -> 0 | BH14: =BA14-BG14 -> 400000
M15: 퇴근 | O15: 0.66666667 | P15: 0.64583333 | Q15: 0.70833333 | R15: 0.66666667 | S15: 0.70833333 | T15: 0.8125 | U15: 0.70833333 | V15: 0.66666667 | W15: 0.64583333 | X15: 0.8125 | Y15: 0.8125 | Z15: 0.8125
M16: 공수 | O16: 1 | P16: 1 | Q16: 1 | R16: 1 | S16: 1 | T16: 1.5
A17: =A14+1 -> 6 | B17: CM006 | C17: 다오 티엔 키우 | D17: DAO TIEN KIEU | E17: 일용 | F17: 931126-5760165 | I17: 하나 346-910639-35707 | J17: 010-7514-9555 | K17: 당진시 신평면 거산리 세정길 29-5 거산타운 다동 302호 | L17: 절단 | M17: 출근 | O17: 0.33333333 | P17: 0.33333333 | Q17: 0.33333333 | R17: 0.33333333 | S17: 0.33333333 | T17: 0.33333333 | U17: 0.33333333 | V17: 0.33333333 | X17: 0.33333333 | Y17: 0.33333333 | Z17: 0.33333333 | AS17: =SUMPRODUCT(--((N17:AR17<>"")+(N18:AR18<>"")>0)) -> 11 | AT17: =IF(OR(E17="일용",E17="사업"&CHAR(10)&"소득"),"일당",IF(E17="시급","시급",IF(E17="월급","월급",""))) -> 일당 | AU17: 130000 | AW17: 200000 | AX17: 200000 | BA17: =SUM(AV17:AZ18) -> 400000 | BE17: 100000 | BG17: =SUM(BB17:BF18) -> 100000 | BH17: =BA17-BG17 -> 300000
M18: 퇴근 | O18: 0.66666667 | P18: 0.64583333 | Q18: 0.70833333 | R18: 0.66666667 | S18: 0.70833333 | T18: 0.70833333 | U18: 0.8125 | V18: 0.66666667 | X18: 0.8125 | Y18: 0.8125 | Z18: 0.91666667
M19: 공수 | O19: 1 | P19: 1 | Q19: 1 | R19: 1 | S19: 1 | T19: 1
A20: =A17+1 -> 7 | B20: CM007 | C20: 린 팍 | D20: RIN PHAK | E20: 시급 | F20: 970709-5760227 | J20: 010-6443-7067 | K20: 당진시 신평면 세정길 29-7,202호 | L20: 사상 | M20: 출근 | O20: 0.33333333 | P20: 0.33333333 | Q20: 0.33333333 | R20: 0.33333333 | S20: 0.33333333 | T20: 0.33333333 | U20: 0.33333333 | V20: 0.33333333 | W20: 0.33333333 | X20: 0.33333333 | Y20: 0.33333333 | Z20: 0.33333333 | AS20: =SUMPRODUCT(--((N20:AR20<>"")+(N21:AR21<>"")>0)) -> 12 | AT20: =IF(OR(E20="일용",E20="사업"&CHAR(10)&"소득"),"일당",IF(E20="시급","시급",IF(E20="월급","월급",""))) -> 시급 | AU20: 10320 | AV20: 1956880 | AW20: 200000 | BA20: =SUM(AV20:AZ21) -> 2156880 | BE20: 100000 | BG20: =SUM(BB20:BF21) -> 100000 | BH20: =BA20-BG20 -> 2056880
M21: 퇴근 | O21: 0.66666667 | P21: 0.64583333 | Q21: 0.70833333 | R21: 0.66666667 | S21: 0.70833333 | T21: 0.70833333 | U21: 0.8125 | V21: 0.66666667 | W21: 0.64583333 | X21: 0.8125 | Y21: 0.8125 | Z21: 0.91666667
M22: 연장
A23: =A20+1 -> 8 | B23: CM008 | C23: 트란 넉 추언 | D23: TRAN NGOC CHUAN | E23: 시급 | F23: 040119-7340017 | J23: 010-8466-5239 | K23: 당진시 신평면 세정길 29-5, 302호 | L23: 사상 | M23: 출근 | O23: 0.33333333 | P23: 0.33333333 | Q23: 0.33333333 | R23: 0.33333333 | S23: 0.33333333 | T23: 0.33333333 | U23: 0.33333333 | V23: 0.33333333 | W23: 0.33333333 | X23: 0.33333333 | Y23: 0.33333333 | Z23: 0.33333333 | AS23: =SUMPRODUCT(--((N23:AR23<>"")+(N24:AR24<>"")>0)) -> 12 | AT23: =IF(OR(E23="일용",E23="사업"&CHAR(10)&"소득"),"일당",IF(E23="시급","시급",IF(E23="월급","월급",""))) -> 시급 | AU23: 10320 | AV23: 1956880 | AW23: 200000 | BA23: =SUM(AV23:AZ24) -> 2156880 | BE23: 100000 | BG23: =SUM(BB23:BF24) -> 100000 | BH23: =BA23-BG23 -> 2056880
M24: 퇴근 | O24: 0.66666667 | P24: 0.64583333 | Q24: 0.70833333 | R24: 0.66666667 | S24: 0.70833333 | T24: 0.70833333 | U24: 0.8125 | V24: 0.66666667 | W24: 0.64583333 | X24: 0.8125 | Y24: 0.8125 | Z24: 0.91666667
M25: 연장
A26: =A23+1 -> 9 | B26: CM009 | C26: 따이 | E26: 시급 | F26: 900408-5180040 | J26: 010-8059-2651 | K26: 당진시 신평면 세정길 29-7,나동 404호 | L26: 마감 | M26: 출근 | O26: 0.33333333 | P26: 0.33333333 | Q26: 0.33333333 | R26: 0.33333333 | S26: 0.33333333 | T26: 0.33333333 | U26: 0.33333333 | V26: 0.33333333 | W26: 0.33333333 | X26: 0.33333333 | Y26: 0.20833333 | Z26: 0.20833333 | AS26: =SUMPRODUCT(--((N26:AR26<>"")+(N27:AR27<>"")>0)) -> 12 | AT26: =IF(OR(E26="일용",E26="사업"&CHAR(10)&"소득"),"일당",IF(E26="시급","시급",IF(E26="월급","월급",""))) -> 시급 | AU26: 10320 | AV26: 1956880 | AW26: 200000 | BA26: =SUM(AV26:AZ27) -> 2156880 | BE26: 100000 | BG26: =SUM(BB26:BF27) -> 100000 | BH26: =BA26-BG26 -> 2056880
M27: 퇴근 | O27: 0.66666667 | P27: 0.64583333 | Q27: 0.70833333 | R27: 0.66666667 | S27: 0.70833333 | T27: 0.8125 | U27: 0.8125 | V27: 0.66666667 | W27: 0.64583333 | X27: 0.91666667 | Y27: 0.91666667 | Z27: 0.91666667
M28: 연장
A29: =A26+1 -> 10 | B29: CM010 | C29: 황피선 | D29: HOANG PHI SON | E29: 시급 | F29: 900425-5200546 | J29: 010-2982-6688 | K29: 당진시 신평면 세정길 29-7,202호 | L29: 취부 | M29: 출근 | O29: 0.33333333 | P29: 0.33333333 | Q29: 0.33333333 | R29: 0.33333333 | S29: 0.33333333 | T29: 0.33333333 | U29: 0.33333333 | V29: 0.33333333 | W29: 0.33333333 | X29: 0.33333333 | Y29: 0.33333333 | Z29: 0.33333333 | AS29: =SUMPRODUCT(--((N29:AR29<>"")+(N30:AR30<>"")>0)) -> 12 | AT29: =IF(OR(E29="일용",E29="사업"&CHAR(10)&"소득"),"일당",IF(E29="시급","시급",IF(E29="월급","월급",""))) -> 시급 | AU29: 10320 | AV29: 1956880 | AW29: 200000 | BA29: =SUM(AV29:AZ30) -> 2156880 | BE29: 100000 | BG29: =SUM(BB29:BF30) -> 100000 | BH29: =BA29-BG29 -> 2056880
M30: 퇴근 | O30: 0.66666667 | P30: 0.64583333 | Q30: 0.70833333 | R30: 0.66666667 | S30: 0.70833333 | T30: 0.70833333 | U30: 0.8125 | V30: 0.66666667 | W30: 0.64583333 | X30: 0.91666667 | Y30: 0.91666667 | Z30: 0.91666667
M31: 연장
A32: =A29+1 -> 11 | B32: CM011 | C32: 이학철 | D32: LI XUEZHE | E32: 사업 소득 | F32: 730512-5800194 | I32: 농협 351-0837-1428-13 | J32: 010-8227-3888 | L32: 마감 | M32: 출근 | O32: 0.33333333 | P32: 0.33333333 | Q32: 0.33333333 | R32: 0.33333333 | S32: 0.33333333 | T32: 0.33333333 | U32: 0.33333333 | V32: 0.33333333 | X32: 0.33333333 | Y32: 0.33333333 | Z32: 0.33333333 | AS32: =SUM(N34:AR34) -> 6 | AT32: =IF(OR(E32="일용",E32="사업"&CHAR(10)&"소득"),"일당",IF(E32="시급","시급",IF(E32="월급","월급",""))) -> 일당 | AU32: 150000 | BA32: =AS32*AU32 -> 900000 | BG32: =SUM(BB32:BF33) -> 0 | BH32: =BA32-BG32 -> 900000
M33: 퇴근 | O33: 0.66666667 | P33: 0.64583333 | Q33: 0.70833333 | R33: 0.5 | S33: 0.70833333 | T33: 0.70833333 | U33: 0.70833333 | V33: 0.66666667 | X33: 0.70833333 | Y33: 0.91666667 | Z33: 0.91666667
M34: 공수 | O34: 1 | P34: 1 | Q34: 1 | R34: 1 | S34: 1 | T34: 1
A35: =A32+1 -> 12 | B35: CM012 | C35: 양명상 | D35: 반빈 | E35: 사업 소득 | F35: PN : C6975015 | I35: 하나 010-974229-82907 | J35: 010-5850-6888 | L35: 용접 | M35: 출근 | O35: 0.33333333 | P35: 0.33333333 | Q35: 0.33333333 | R35: 0.33333333 | S35: 0.33333333 | T35: 0.33333333 | V35: 0.33333333 | W35: 0.33333333 | X35: 0.33333333 | Y35: 0.20833333 | Z35: 0.20833333 | AS35: =SUMPRODUCT(--((N35:AR35<>"")+(N36:AR36<>"")>0)) -> 11 | AT35: =IF(OR(E35="일용",E35="사업"&CHAR(10)&"소득"),"일당",IF(E35="시급","시급",IF(E35="월급","월급",""))) -> 일당 | AU35: 180000 | BA35: =AS35*AU35 -> 1980000 | BG35: =SUM(BB35:BF36) -> 0 | BH35: =BA35-BG35 -> 1980000
M36: 퇴근 | O36: 0.66666667 | P36: 0.64583333 | Q36: 0.70833333 | R36: 0.66666667 | S36: 0.70833333 | T36: 0.8125 | V36: 0.66666667 | W36: 0.64583333 | X36: 0.8125 | Y36: 0.8125 | Z36: 0.8125
M37: 공수 | O37: 1 | P37: 1 | Q37: 1 | R37: 1 | S37: 1 | T37: 1.5
A38: =A35+1 -> 13 | B38: CM013 | C38: 조귀선 | E38: 사업 소득 | F38: 610304-1030512 | I38: 농협 356-0381-9126-83 | J38: 010-8543-6645 | K38: 경상남도 칠곡군 왜관읍 석진로 77,101동 209호(한빛타운) | L38: 절단 | M38: 출근 | Q38: 0.33333333 | R38: 0.33333333 | S38: 0.33333333 | T38: 0.33333333 | U38: 0.33333333 | V38: 0.33333333 | W38: 0.33333333 | X38: 0.33333333 | Y38: 0.33333333 | Z38: 0.33333333 | AS38: =SUMPRODUCT(--((N38:AR38<>"")+(N39:AR39<>"")>0)) -> 10 | AT38: =IF(OR(E38="일용",E38="사업"&CHAR(10)&"소득"),"일당",IF(E38="시급","시급",IF(E38="월급","월급",""))) -> 일당 | AU38: 200000 | BA38: =AS38*AU38 -> 2000000 | BG38: =SUM(BB38:BF39) -> 0 | BH38: =BA38-BG38 -> 2000000
M39: 퇴근 | Q39: 0.70833333 | R39: 0.66666667 | S39: 0.70833333 | T39: 0.8125 | U39: 0.70833333 | V39: 0.66666667 | W39: 0.64583333 | X39: 0.8125 | Y39: 0.8125 | Z39: 0.8125
M40: 공수 | Q40: 1 | R40: 1 | S40: 1 | T40: 1.5
...

Sheet 공휴일테이블
A1: 날짜 | B1: 공휴일명
A2: 46023 | B2: 신정
A3: 46082 | B3: 삼일절
A4: 46143 | B4: 근로자의날
A5: 46147 | B5: 어린이날
A6: 46179 | B6: 현충일
A7: 46249 | B7: 광복절
A8: 46298 | B8: 개천절
A9: 46304 | B9: 한글날
A10: 46381 | B10: 성탄절
A11: 46388 | B11: 신정
A12: 46447 | B12: 삼일절
A13: 46508 | B13: 근로자의날
... A46: 47842 | B46: 성탄절

Sheet 급여대장(월급,일용,시급)
B1: ='2026년5월전체'!S1&"년 "&'2026년5월전체'!V1&"월 급여대장" -> 2026년 5월 급여대장
B2: 급 여 산 정 기 간 : | D2: =TEXT(DATE('2026년5월전체'!S1,'2026년5월전체'!V1,1),"yyyy.m.d")&" ~ "&TEXT(EOMONTH(DATE('2026년5월전체'!S1,'2026년5월전체'!V1,1),0),"yyyy.m.d") -> 2026.5.1 ~ 2026.5.31 | K2: 지 급 일 : | M2: =DATE('2026년5월전체'!S1,'2026년5월전체'!V1+1,15) -> 46188
B3: 순번 | C3: 인적사항 | D3: 공수 | E3: 기 본 급 여 및 제 수 당 | J3: 제 공 제 및 월 수 령 액
C4: 성 명 | D4: 단가 | E4: 기본급 | F4: 식대 | G4: 자가운전 | H4: 통신비 | I4: 직책수당 | J4: 국민연금 | K4: 건강보험 | L4: 장기요양보험 | M4: 고용보험 | N4: 가 불 | O4: 공제총액
C5: 입 사 일 | E5: 연장수당 | F5: 휴일수당 | G5: 성과금 | H5: 직책수당 | I5: 지급총액 | J5: 소 득 세 | K5: 주 민 세 | L5: 숙소료 | M5: 건강보험정산 | O5: 월수령액
B6: 1 | C6: ='2026년5월전체'!C7 -> 정찬영 | D6: =IF(OR('2026년5월전체'!E7="일용",'2026년5월전체'!E7="시급"),'2026년5월전체'!AS7,"") | E6: ='2026년5월전체'!AV7 -> 4600000 | F6: ='2026년5월전체'!AW7 -> 200000 | G6: ='2026년5월전체'!AX7 -> 200000 | H6: ='2026년5월전체'!AY7 -> 100000 | I6: ='2026년5월전체'!AZ7 -> 0 | J6: ='2026년5월전체'!BB7 -> 0 | K6: ='2026년5월전체'!BC7 -> 0 | L6: ='2026년5월전체'!BD7 -> 0 | M6: ='2026년5월전체'!BE7 -> 0 | N6: ='2026년5월전체'!BF7 -> 0 | O6: =SUM(J6:N6,J7:N7) -> 0
C7: ='2026년5월전체'!G7 -> 45870 | D7: =IF(OR('2026년5월전체'!E7="일용",'2026년5월전체'!E7="시급"),'2026년5월전체'!AU7,"") | E7: ='2026년5월전체'!AV8 -> 0 | F7: ='2026년5월전체'!AW8 -> 0 | G7: ='2026년5월전체'!AX8 -> 0 | H7: ='2026년5월전체'!AY8 -> 0 | I7: =SUM(E6:I6,E7:H7) -> 5100000 | J7: ='2026년5월전체'!BB8 -> 0 | K7: ='2026년5월전체'!BC8 -> 0 | L7: ='2026년5월전체'!BD8 -> 0 | M7: ='2026년5월전체'!BE8 -> 0 | N7: ='2026년5월전체'!BF8 -> 0 | O7: =I7-O6 -> 5100000
B8: 2 | C8: ='2026년5월전체'!C10 -> 박정선 | D8: =IF(OR('2026년5월전체'!E10="일용",'2026년5월전체'!E10="시급"),'2026년5월전체'!AS10,"") | E8: ='2026년5월전체'!AV10 -> 3800000 | F8: ='2026년5월전체'!AW10 -> 200000 | G8: ='2026년5월전체'!AX10 -> 0 | H8: ='2026년5월전체'!AY10 -> 0 | I8: ='2026년5월전체'!AZ10 -> 0 | J8: ='2026년5월전체'!BB10 -> 0 | K8: ='2026년5월전체'!BC10 -> 0 | L8: ='2026년5월전체'!BD10 -> 0 | M8: ='2026년5월전체'!BE10 -> 0 | N8: ='2026년5월전체'!BF10 -> 0 | O8: =SUM(J8:N8,J9:N9) -> 0
C9: ='2026년5월전체'!G10 -> 45870 | D9: =IF(OR('2026년5월전체'!E10="일용",'2026년5월전체'!E10="시급"),'2026년5월전체'!AU10,"") | E9: ='2026년5월전체'!AV11 -> 0 | F9: ='2026년5월전체'!AW11 -> 0 | G9: ='2026년5월전체'!AX11 -> 0 | H9: ='2026년5월전체'!AY11 -> 0 | I9: =SUM(E8:I8,E9:H9) -> 4000000 | J9: ='2026년5월전체'!BB11 -> 0 | K9: ='2026년5월전체'!BC11 -> 0 | L9: ='2026년5월전체'!BD11 -> 0 | M9: ='2026년5월전체'!BE11 -> 0 | N9: ='2026년5월전체'!BF11 -> 0 | O9: =I9-O8 -> 4000000
B10: 3 | C10: ='2026년5월전체'!C12 -> 문지수 | D10: =IF(OR('2026년5월전체'!E12="일용",'2026년5월전체'!E12="시급"),'2026년5월전체'!AS12,"") | E10: ='2026년5월전체'!AV12 -> 2800000 | F10: ='2026년5월전체'!AW12 -> 200000 | G10: ='2026년5월전체'!AX12 -> 0 | H10: ='2026년5월전체'!AY12 -> 0 | I10: ='2026년5월전체'!AZ12 -> 0 | J10: ='2026년5월전체'!BB12 -> 0 | K10: ='2026년5월전체'!BC12 -> 0 | L10: ='2026년5월전체'!BD12 -> 0 | M10: ='2026년5월전체'!BE12 -> 0 | N10: ='2026년5월전체'!BF12 -> 0 | O10: =SUM(J10:N10,J11:N11) -> 0
C11: ='2026년5월전체'!G12 -> 45870 | D11: =IF(OR('2026년5월전체'!E12="일용",'2026년5월전체'!E12="시급"),'2026년5월전체'!AU12,"") | E11: ='2026년5월전체'!AV13 -> 0 | F11: ='2026년5월전체'!AW13 -> 0 | G11: ='2026년5월전체'!AX13 -> 0 | H11: ='2026년5월전체'!AY13 -> 0 | I11: =SUM(E10:I10,E11:H11) -> 3000000 | J11: ='2026년5월전체'!BB13 -> 0 | K11: ='2026년5월전체'!BC13 -> 0 | L11: ='2026년5월전체'!BD13 -> 0 | M11: ='2026년5월전체'!BE13 -> 0 | N11: ='2026년5월전체'!BF13 -> 0 | O11: =I11-O10 -> 3000000
B12: 4 | C12: ='2026년5월전체'!C14 -> 김인진 | D12: =IF(OR('2026년5월전체'!E14="일용",'2026년5월전체'!E14="시급"),'2026년5월전체'!AS14,"") -> 12 | E12: ='2026년5월전체'!AV14 -> 0 | F12: ='2026년5월전체'!AW14 -> 200000 | G12: ='2026년5월전체'!AX14 -> 200000 | H12: ='2026년5월전체'!AY14 -> 0 | I12: ='2026년5월전체'!AZ14 -> 0 | J12: ='2026년5월전체'!BB14 -> 0 | K12: ='2026년5월전체'!BC14 -> 0 | L12: ='2026년5월전체'!BD14 -> 0 | M12: ='2026년5월전체'!BE14 -> 0 | N12: ='2026년5월전체'!BF14 -> 0 | O12: =SUM(J12:N12,J13:N13) -> 0
C13: ='2026년5월전체'!G14 -> 45870 | D13: =IF(OR('2026년5월전체'!E14="일용",'2026년5월전체'!E14="시급"),'2026년5월전체'!AU14,"") -> 160000 | E13: ='2026년5월전체'!AV15 -> 0 | F13: ='2026년5월전체'!AW15 -> 0 | G13: ='2026년5월전체'!AX15 -> 0 | H13: ='2026년5월전체'!AY15 -> 0 | I13: =SUM(E12:I12,E13:H13) -> 400000 | J13: ='2026년5월전체'!BB15 -> 0 | K13: ='2026년5월전체'!BC15 -> 0 | L13: ='2026년5월전체'!BD15 -> 0 | M13: ='2026년5월전체'!BE15 -> 0 | N13: ='2026년5월전체'!BF15 -> 0 | O13: =I13-O12 -> 400000
B14: 5 | C14: ='2026년5월전체'!C17 -> 다오 티엔 키우 | D14: =IF(OR('2026년5월전체'!E17="일용",'2026년5월전체'!E17="시급"),'2026년5월전체'!AS17,"") -> 11 | E14: ='2026년5월전체'!AV17 -> 0 | F14: ='2026년5월전체'!AW17 -> 200000 | G14: ='2026년5월전체'!AX17 -> 200000 | H14: ='2026년5월전체'!AY17 -> 0 | I14: ='2026년5월전체'!AZ17 -> 0 | J14: ='2026년5월전체'!BB17 -> 0 | K14: ='2026년5월전체'!BC17 -> 0 | L14: ='2026년5월전체'!BD17 -> 0 | M14: ='2026년5월전체'!BE17 -> 100000 | N14: ='2026년5월전체'!BF17 -> 0 | O14: =SUM(J14:N14,J15:N15) -> 100000
C15: ='2026년5월전체'!G17 -> 0 | D15: =IF(OR('2026년5월전체'!E17="일용",'2026년5월전체'!E17="시급"),'2026년5월전체'!AU17,"") -> 130000 | E15: ='2026년5월전체'!AV18 -> 0 | F15: ='2026년5월전체'!AW18 -> 0 | G15: ='2026년5월전체'!AX18 -> 0 | H15: ='2026년5월전체'!AY18 -> 0 | I15: =SUM(E14:I14,E15:H15) -> 400000 | J15: ='2026년5월전체'!BB18 -> 0 | K15: ='2026년5월전체'!BC18 -> 0 | L15: ='2026년5월전체'!BD18 -> 0 | M15: ='2026년5월전체'!BE18 -> 0 | N15: ='2026년5월전체'!BF18 -> 0 | O15: =I15-O14 -> 300000
B16: 6 | C16: ='2026년5월전체'!C20 -> 린 팍 | D16: =IF(OR('2026년5월전체'!E20="일용",'2026년5월전체'!E20="시급"),'2026년5월전체'!AS20,"") -> 12 | E16: ='2026년5월전체'!AV20 -> 1956880 | F16: ='2026년5월전체'!AW20 -> 200000 | G16: ='2026년5월전체'!AX20 -> 0 | H16: ='2026년5월전체'!AY20 -> 0 | I16: ='2026년5월전체'!AZ20 -> 0 | J16: ='2026년5월전체'!BB20 -> 0 | K16: ='2026년5월전체'!BC20 -> 0 | L16: ='2026년5월전체'!BD20 -> 0 | M16: ='2026년5월전체'!BE20 -> 100000 | N16: ='2026년5월전체'!BF20 -> 0 | O16: =SUM(J16:N16,J17:N17) -> 100000
C17: ='2026년5월전체'!G20 -> 0 | D17: =IF(OR('2026년5월전체'!E20="일용",'2026년5월전체'!E20="시급"),'2026년5월전체'!AU20,"") -> 10320 | E17: ='2026년5월전체'!AV21 -> 0 | F17: ='2026년5월전체'!AW21 -> 0 | G17: ='2026년5월전체'!AX21 -> 0 | H17: ='2026년5월전체'!AY21 -> 0 | I17: =SUM(E16:I16,E17:H17) -> 2156880 | J17: ='2026년5월전체'!BB21 -> 0 | K17: ='2026년5월전체'!BC21 -> 0 | L17: ='2026년5월전체'!BD21 -> 0 | M17: ='2026년5월전체'!BE21 -> 0 | N17: ='2026년5월전체'!BF21 -> 0 | O17: =I17-O16 -> 2056880
B18: 7 | C18: ='2026년5월전체'!C23 -> 트란 넉 추언 | D18: =IF(OR('2026년5월전체'!E23="일용",'2026년5월전체'!E23="시급"),'2026년5월전체'!AS23,"") -> 12 | E18: ='2026년5월전체'!AV23 -> 1956880 | F18: ='2026년5월전체'!AW23 -> 200000 | G18: ='2026년5월전체'!AX23 -> 0 | H18: ='2026년5월전체'!AY23 -> 0 | I18: ='2026년5월전체'!AZ23 -> 0 | J18: ='2026년5월전체'!BB23 -> 0 | K18: ='2026년5월전체'!BC23 -> 0 | L18: ='2026년5월전체'!BD23 -> 0 | M18: ='2026년5월전체'!BE23 -> 100000 | N18: ='2026년5월전체'!BF23 -> 0 | O18: =SUM(J18:N18,J19:N19) -> 100000
C19: ='2026년5월전체'!G23 -> 0 | D19: =IF(OR('2026년5월전체'!E23="일용",'2026년5월전체'!E23="시급"),'2026년5월전체'!AU23,"") -> 10320 | E19: ='2026년5월전체'!AV24 -> 0 | F19: ='2026년5월전체'!AW24 -> 0 | G19: ='2026년5월전체'!AX24 -> 0 | H19: ='2026년5월전체'!AY24 -> 0 | I19: =SUM(E18:I18,E19:H19) -> 2156880 | J19: ='2026년5월전체'!BB24 -> 0 | K19: ='2026년5월전체'!BC24 -> 0 | L19: ='2026년5월전체'!BD24 -> 0 | M19: ='2026년5월전체'!BE24 -> 0 | N19: ='2026년5월전체'!BF24 -> 0 | O19: =I19-O18 -> 2056880
B20: 8 | C20: ='2026년5월전체'!C26 -> 따이 | D20: =IF(OR('2026년5월전체'!E26="일용",'2026년5월전체'!E26="시급"),'2026년5월전체'!AS26,"") -> 12 | E20: ='2026년5월전체'!AV26 -> 1956880 | F20: ='2026년5월전체'!AW26 -> 200000 | G20: ='2026년5월전체'!AX26 -> 0 | H20: ='2026년5월전체'!AY26 -> 0 | I20: ='2026년5월전체'!AZ26 -> 0 | J20: ='2026년5월전체'!BB26 -> 0 | K20: ='2026년5월전체'!BC26 -> 0 | L20: ='2026년5월전체'!BD26 -> 0 | M20: ='2026년5월전체'!BE26 -> 100000 | N20: ='2026년5월전체'!BF26 -> 0 | O20: =SUM(J20:N20,J21:N21) -> 100000
C21: ='2026년5월전체'!G26 -> 0 | D21: =IF(OR('2026년5월전체'!E26="일용",'2026년5월전체'!E26="시급"),'2026년5월전체'!AU26,"") -> 10320 | E21: ='2026년5월전체'!AV27 -> 0 | F21: ='2026년5월전체'!AW27 -> 0 | G21: ='2026년5월전체'!AX27 -> 0 | H21: ='2026년5월전체'!AY27 -> 0 | I21: =SUM(E20:I20,E21:H21) -> 2156880 | J21: ='2026년5월전체'!BB27 -> 0 | K21: ='2026년5월전체'!BC27 -> 0 | L21: ='2026년5월전체'!BD27 -> 0 | M21: ='2026년5월전체'!BE27 -> 0 | N21: ='2026년5월전체'!BF27 -> 0 | O21: =I21-O20 -> 2056880
B22: 9 | C22: ='2026년5월전체'!C29 -> 황피선 | D22: =IF(OR('2026년5월전체'!E29="일용",'2026년5월전체'!E29="시급"),'2026년5월전체'!AS29,"") -> 12 | E22: ='2026년5월전체'!AV29 -> 1956880 | F22: ='2026년5월전체'!AW29 -> 200000 | G22: ='2026년5월전체'!AX29 -> 0 | H22: ='2026년5월전체'!AY29 -> 0 | I22: ='2026년5월전체'!AZ29 -> 0 | J22: ='2026년5월전체'!BB29 -> 0 | K22: ='2026년5월전체'!BC29 -> 0 | L22: ='2026년5월전체'!BD29 -> 0 | M22: ='2026년5월전체'!BE29 -> 100000 | N22: ='2026년5월전체'!BF29 -> 0 | O22: =SUM(J22:N22,J23:N23) -> 100000
C23: ='2026년5월전체'!G29 -> 0 | D23: =IF(OR('2026년5월전체'!E29="일용",'2026년5월전체'!E29="시급"),'2026년5월전체'!AU29,"") -> 10320 | E23: ='2026년5월전체'!AV30 -> 0 | F23: ='2026년5월전체'!AW30 -> 0 | G23: ='2026년5월전체'!AX30 -> 0 | H23: ='2026년5월전체'!AY30 -> 0 | I23: =SUM(E22:I22,E23:H23) -> 2156880 | J23: ='2026년5월전체'!BB30 -> 0 | K23: ='2026년5월전체'!BC30 -> 0 | L23: ='2026년5월전체'!BD30 -> 0 | M23: ='2026년5월전체'!BE30 -> 0 | N23: ='2026년5월전체'!BF30 -> 0 | O23: =I23-O22 -> 2056880
B30: 계 | E30: =E6+E8+E10+E12+E14+E16+E18+E20+E22+E24+E26+E28 -> 19027520 | F30: =F6+F8+F10+F12+F14+F16+F18+F20+F22+F24+F26+F28 -> 1800000 | G30: =G6+G8+G10+G12+G14+G16+G18+G20+G22+G24+G26+G28 -> 600000 | H30: =H6+H8+H10+H12+H14+H16+H18+H20+H22+H24+H26+H28 -> 100000 | I30: =I6+I8+I10+I12+I14+I16+I18+I20+I22+I24+I26+I28 -> 0 | J30: =J6+J8+J10+J12+J14+J16+J18+J20+J22+J24+J26+J28 -> 0 | K30: =K6+K8+K10+K12+K14+K16+K18+K20+K22+K24+K26+K28 -> 0 | L30: =L6+L8+L10+L12+L14+L16+L18+L20+L22+L24+L26+L28 -> 0 | M30: =M6+M8+M10+M12+M14+M16+M18+M20+M22+M24+M26+M28 -> 500000 | O30: =SUM(J30:N30,J31:N31) -> 500000
E31: =E7+E9+E11+E13+E15+E17+E19+E21+E23+E25+E27+E29 -> 0 | F31: =F7+F9+F11+F13+F15+F17+F19+F21+F23+F25+F27+F29 -> 0 | G31: =G7+G9+G11+G13+G15+G17+G19+G21+G23+G25+G27+G29 -> 0 | H31: =H7+H9+H11+H13+H15+H17+H19+H21+H23+H25+H27+H29 -> 0 | I31: =I7+I9+I11+I13+I15+I17+I19+I21+I23+I25+I27+I29 -> 21527520 | J31: =J7+J9+J11+J13+J15+J17+J19+J21+J23+J25+J27+J29 -> 0 | K31: =K7+K9+K11+K13+K15+K17+K19+K21+K23+K25+K27+K29 -> 0 | L31: =L7+L9+L11+L13+L15+L17+L19+L21+L23+L25+L27+L29 -> 0 | M31: =M7+M9+M11+M13+M15+M17+M19+M21+M23+M25+M27+M29 -> 0 | O31: =I31-O30 -> 21027520

Sheet 급여대장(사업소득자)
B1: ='2026년5월전체'!S1&"년 "&'2026년5월전체'!V1&"월 급여대장" -> 2026년 5월 급여대장
B2: 급 여 산 정 기 간 : | D2: =TEXT(DATE('2026년5월전체'!S1,'2026년5월전체'!V1,1),"yyyy.m.d")&" ~ "&TEXT(EOMONTH(DATE('2026년5월전체'!S1,'2026년5월전체'!V1,1),0),"yyyy.m.d") -> 2026.5.1 ~ 2026.5.31 | L2: 지 급 일 : | N2: =DATE('2026년5월전체'!S1,'2026년5월전체'!V1+1,15) -> 46188
B3: 순번 | C3: 인적사항 | D3: 공수 | E3: 기 본 급 여 및 제 수 당 | K3: 제 공 제 및 월 수 령 액
C4: 성 명 | D4: 단가 | E4: 기본급 | F4: 식대 | G4: 자가운전 | H4: 통신비 | I4: 직책수당 | K4: 국민연금 | L4: 건강보험 | M4: 장기요양보험 | N4: 고용보험 | O4: 기타 | P4: 공제총액
C5: 입 사 일 | E5: 연장수당 | F5: 휴일수당 | G5: 휴일연장 | H5: 심야수당 | I5: 기타 | J5: 지급총액 | K5: 소 득 세 | L5: 주 민 세 | M5: 숙소료 | N5: 가불 | P5: 월수령액
B6: 1 | C6: ='2026년5월전체'!C32 -> 이학철 | D6: ='2026년5월전체'!AS32 -> 6 | E6: ='2026년5월전체'!AV32 -> 0 | F6: ='2026년5월전체'!AW32 -> 0 | G6: ='2026년5월전체'!AX32 -> 0 | H6: ='2026년5월전체'!AY32 -> 0 | I6: ='2026년5월전체'!AZ32 -> 0 | K6: ='2026년5월전체'!BB32 -> 0 | L6: ='2026년5월전체'!BC32 -> 0 | M6: ='2026년5월전체'!BD32 -> 0 | N6: ='2026년5월전체'!BE32 -> 0 | O6: ='2026년5월전체'!BF32 -> 0 | P6: =SUM(K6:O6,K7:O7) -> 0
C7: ='2026년5월전체'!G32 -> 0 | D7: ='2026년5월전체'!AU32 -> 150000 | E7: ='2026년5월전체'!AV33 -> 0 | F7: ='2026년5월전체'!AW33 -> 0 | G7: ='2026년5월전체'!AX33 -> 0 | H7: ='2026년5월전체'!AY33 -> 0 | I7: ='2026년5월전체'!AZ33 -> 0 | J7: =SUM(E6:I6,E7:I7) -> 0 | K7: ='2026년5월전체'!BB33 -> 0 | L7: ='2026년5월전체'!BC33 -> 0 | M7: ='2026년5월전체'!BD33 -> 0 | N7: ='2026년5월전체'!BE33 -> 0 | O7: ='2026년5월전체'!BF33 -> 0 | P7: =J7-P6 -> 0
B8: 2 | C8: ='2026년5월전체'!C35 -> 양명상 | D8: ='2026년5월전체'!AS35 -> 11 | E8: ='2026년5월전체'!AV35 -> 0 | F8: ='2026년5월전체'!AW35 -> 0 | G8: ='2026년5월전체'!AX35 -> 0 | H8: ='2026년5월전체'!AY35 -> 0 | I8: ='2026년5월전체'!AZ35 -> 0 | K8: ='2026년5월전체'!BB35 -> 0 | L8: ='2026년5월전체'!BC35 -> 0 | M8: ='2026년5월전체'!BD35 -> 0 | N8: ='2026년5월전체'!BE35 -> 0 | O8: ='2026년5월전체'!BF35 -> 0 | P8: =SUM(K8:O8,K9:O9) -> 0
C9: ='2026년5월전체'!G35 -> 0 | D9: ='2026년5월전체'!AU35 -> 180000 | E9: ='2026년5월전체'!AV36 -> 0 | F9: ='2026년5월전체'!AW36 -> 0 | G9: ='2026년5월전체'!AX36 -> 0 | H9: ='2026년5월전체'!AY36 -> 0 | I9: ='2026년5월전체'!AZ36 -> 0 | J9: =SUM(E8:I8,E9:I9) -> 0 | K9: ='2026년5월전체'!BB36 -> 0 | L9: ='2026년5월전체'!BC36 -> 0 | M9: ='2026년5월전체'!BD36 -> 0 | N9: ='2026년5월전체'!BE36 -> 0 | O9: ='2026년5월전체'!BF36 -> 0 | P9: =J9-P8 -> 0
B10: 3 | C10: ='2026년5월전체'!C38 -> 조귀선 | D10: ='2026년5월전체'!AS38 -> 10 | E10: ='2026년5월전체'!AV38 -> 0 | F10: ='2026년5월전체'!AW38 -> 0 | G10: ='2026년5월전체'!AX38 -> 0 | H10: ='2026년5월전체'!AY38 -> 0 | I10: ='2026년5월전체'!AZ38 -> 0 | K10: ='2026년5월전체'!BB38 -> 0 | L10: ='2026년5월전체'!BC38 -> 0 | M10: ='2026년5월전체'!BD38 -> 0 | N10: ='2026년5월전체'!BE38 -> 0 | O10: ='2026년5월전체'!BF38 -> 0 | P10: =SUM(K10:O10,K11:O11) -> 0
C11: ='2026년5월전체'!G38 -> 0 | D11: ='2026년5월전체'!AU38 -> 200000 | E11: ='2026년5월전체'!AV39 -> 0 | F11: ='2026년5월전체'!AW39 -> 0 | G11: ='2026년5월전체'!AX39 -> 0 | H11: ='2026년5월전체'!AY39 -> 0 | I11: ='2026년5월전체'!AZ39 -> 0 | J11: =SUM(E10:I10,E11:I11) -> 0 | K11: ='2026년5월전체'!BB39 -> 0 | L11: ='2026년5월전체'!BC39 -> 0 | M11: ='2026년5월전체'!BD39 -> 0 | N11: ='2026년5월전체'!BE39 -> 0 | O11: ='2026년5월전체'!BF39 -> 0 | P11: =J11-P10 -> 0
B12: 4 | C12: ='2026년5월전체'!C41 -> 이재훈 | D12: ='2026년5월전체'!AS41 -> 11 | E12: ='2026년5월전체'!AV41 -> 0 | F12: ='2026년5월전체'!AW41 -> 0 | G12: ='2026년5월전체'!AX41 -> 0 | H12: ='2026년5월전체'!AY41 -> 0 | I12: ='2026년5월전체'!AZ41 -> 0 | K12: ='2026년5월전체'!BB41 -> 0 | L12: ='2026년5월전체'!BC41 -> 0 | M12: ='2026년5월전체'!BD41 -> 0 | N12: ='2026년5월전체'!BE41 -> 0 | O12: ='2026년5월전체'!BF41 -> 0 | P12: =SUM(K12:O12,K13:O13) -> 0
C13: ='2026년5월전체'!G41 -> 0 | D13: ='2026년5월전체'!AU41 -> 200000 | E13: ='2026년5월전체'!AV42 -> 0 | F13: ='2026년5월전체'!AW42 -> 0 | G13: ='2026년5월전체'!AX42 -> 0 | H13: ='2026년5월전체'!AY42 -> 0 | I13: ='2026년5월전체'!AZ42 -> 0 | J13: =SUM(E12:I12,E13:I13) -> 0 | K13: ='2026년5월전체'!BB42 -> 0 | L13: ='2026년5월전체'!BC42 -> 0 | M13: ='2026년5월전체'!BD42 -> 0 | N13: ='2026년5월전체'!BE42 -> 0 | O13: ='2026년5월전체'!BF42 -> 0 | P13: =J13-P12 -> 0
B14: 5 | C14: ='2026년5월전체'!C44 -> 장기문 | D14: ='2026년5월전체'!AS44 -> 10 | E14: ='2026년5월전체'!AV44 -> 0 | F14: ='2026년5월전체'!AW44 -> 0 | G14: ='2026년5월전체'!AX44 -> 0 | H14: ='2026년5월전체'!AY44 -> 0 | I14: ='2026년5월전체'!AZ44 -> 0 | K14: ='2026년5월전체'!BB44 -> 0 | L14: ='2026년5월전체'!BC44 -> 0 | M14: ='2026년5월전체'!BD44 -> 0 | N14: ='2026년5월전체'!BE44 -> 0 | O14: ='2026년5월전체'!BF44 -> 0 | P14: =SUM(K14:O14,K15:O15) -> 0
C15: ='2026년5월전체'!G44 -> 0 | D15: ='2026년5월전체'!AU44 -> 200000 | E15: ='2026년5월전체'!AV45 -> 0 | F15: ='2026년5월전체'!AW45 -> 0 | G15: ='2026년5월전체'!AX45 -> 0 | H15: ='2026년5월전체'!AY45 -> 0 | I15: ='2026년5월전체'!AZ45 -> 0 | J15: =SUM(E14:I14,E15:I15) -> 0 | K15: ='2026년5월전체'!BB45 -> 0 | L15: ='2026년5월전체'!BC45 -> 0 | M15: ='2026년5월전체'!BD45 -> 0 | N15: ='2026년5월전체'!BE45 -> 0 | O15: ='2026년5월전체'!BF45 -> 0 | P15: =J15-P14 -> 0
B16: 6 | C16: ='2026년5월전체'!C47 -> 이미옥 | D16: ='2026년5월전체'!AS47 -> 11 | E16: ='2026년5월전체'!AV47 -> 0 | F16: ='2026년5월전체'!AW47 -> 0 | G16: ='2026년5월전체'!AX47 -> 0 | H16: ='2026년5월전체'!AY47 -> 0 | I16: ='2026년5월전체'!AZ47 -> 0 | K16: ='2026년5월전체'!BB47 -> 0 | L16: ='2026년5월전체'!BC47 -> 0 | M16: ='2026년5월전체'!BD47 -> 0 | N16: ='2026년5월전체'!BE47 -> 0 | O16: ='2026년5월전체'!BF47 -> 0 | P16: =SUM(K16:O16,K17:O17) -> 0
C17: ='2026년5월전체'!G47 -> 0 | D17: ='2026년5월전체'!AU47 -> 150000 | E17: ='2026년5월전체'!AV48 -> 0 | F17: ='2026년5월전체'!AW48 -> 0 | G17: ='2026년5월전체'!AX48 -> 0 | H17: ='2026년5월전체'!AY48 -> 0 | I17: ='2026년5월전체'!AZ48 -> 0 | J17: =SUM(E16:I16,E17:I17) -> 0 | K17: ='2026년5월전체'!BB48 -> 0 | L17: ='2026년5월전체'!BC48 -> 0 | M17: ='2026년5월전체'!BD48 -> 0 | N17: ='2026년5월전체'!BE48 -> 0 | O17: ='2026년5월전체'!BF48 -> 0 | P17: =J17-P16 -> 0
B18: 7 | C18: ='2026년5월전체'!C50 -> 원평지 | D18: ='2026년5월전체'!AS50 -> 10 | E18: ='2026년5월전체'!AV50 -> 0 | F18: ='2026년5월전체'!AW50 -> 0 | G18: ='2026년5월전체'!AX50 -> 0 | H18: ='2026년5월전체'!AY50 -> 0 | I18: ='2026년5월전체'!AZ50 -> 0 | K18: ='2026년5월전체'!BB50 -> 0 | L18: ='2026년5월전체'!BC50 -> 0 | M18: ='2026년5월전체'!BD50 -> 0 | N18: ='2026년5월전체'!BE50 -> 0 | O18: ='2026년5월전체'!BF50 -> 0 | P18: =SUM(K18:O18,K19:O19) -> 0
C19: ='2026년5월전체'!G50 -> 0 | D19: ='2026년5월전체'!AU50 -> 150000 | E19: ='2026년5월전체'!AV51 -> 0 | F19: ='2026년5월전체'!AW51 -> 0 | G19: ='2026년5월전체'!AX51 -> 0 | H19: ='2026년5월전체'!AY51 -> 0 | I19: ='2026년5월전체'!AZ51 -> 0 | J19: =SUM(E18:I18,E19:I19) -> 0 | K19: ='2026년5월전체'!BB51 -> 0 | L19: ='2026년5월전체'!BC51 -> 0 | M19: ='2026년5월전체'!BD51 -> 0 | N19: ='2026년5월전체'!BE51 -> 0 | O19: ='2026년5월전체'!BF51 -> 0 | P19: =J19-P18 -> 0
B20: 8 | C20: ='2026년5월전체'!C53 -> 김성산 | D20: ='2026년5월전체'!AS53 -> 8 | E20: ='2026년5월전체'!AV53 -> 0 | F20: ='2026년5월전체'!AW53 -> 0 | G20: ='2026년5월전체'!AX53 -> 0 | H20: ='2026년5월전체'!AY53 -> 0 | I20: ='2026년5월전체'!AZ53 -> 0 | K20: ='2026년5월전체'!BB53 -> 0 | L20: ='2026년5월전체'!BC53 -> 0 | M20: ='2026년5월전체'!BD53 -> 0 | N20: ='2026년5월전체'!BE53 -> 0 | O20: ='2026년5월전체'!BF53 -> 0 | P20: =SUM(K20:O20,K21:O21) -> 0
C21: ='2026년5월전체'!G53 -> 0 | D21: ='2026년5월전체'!AU53 -> 150000 | E21: ='2026년5월전체'!AV54 -> 0 | F21: ='2026년5월전체'!AW54 -> 0 | G21: ='2026년5월전체'!AX54 -> 0 | H21: ='2026년5월전체'!AY54 -> 0 | I21: ='2026년5월전체'!AZ54 -> 0 | J21: =SUM(E20:I20,E21:I21) -> 0 | K21: ='2026년5월전체'!BB54 -> 0 | L21: ='2026년5월전체'!BC54 -> 0 | M21: ='2026년5월전체'!BD54 -> 0 | N21: ='2026년5월전체'!BE54 -> 0 | O21: ='2026년5월전체'!BF54 -> 0 | P21: =J21-P20 -> 0
B22: 9 | C22: ='2026년5월전체'!C56 -> 서승길 | D22: ='2026년5월전체'!AS56 -> 3 | E22: ='2026년5월전체'!AV56 -> 0 | F22: ='2026년5월전체'!AW56 -> 0 | G22: ='2026년5월전체'!AX56 -> 0 | H22: ='2026년5월전체'!AY56 -> 0 | I22: ='2026년5월전체'!AZ56 -> 0 | K22: ='2026년5월전체'!BB56 -> 0 | L22: ='2026년5월전체'!BC56 -> 0 | M22: ='2026년5월전체'!BD56 -> 0 | N22: ='2026년5월전체'!BE56 -> 0 | O22: ='2026년5월전체'!BF56 -> 0 | P22: =SUM(K22:O22,K23:O23) -> 0
C23: ='2026년5월전체'!G56 -> 0 | D23: ='2026년5월전체'!AU56 -> 150000 | E23: ='2026년5월전체'!AV57 -> 0 | F23: ='2026년5월전체'!AW57 -> 0 | G23: ='2026년5월전체'!AX57 -> 0 | H23: ='2026년5월전체'!AY57 -> 0 | I23: ='2026년5월전체'!AZ57 -> 0 | J23: =SUM(E22:I22,E23:I23) -> 0 | K23: ='2026년5월전체'!BB57 -> 0 | L23: ='2026년5월전체'!BC57 -> 0 | M23: ='2026년5월전체'!BD57 -> 0 | N23: ='2026년5월전체'!BE57 -> 0 | O23: ='2026년5월전체'!BF57 -> 0 | P23: =J23-P22 -> 0
B24: 10 | C24: ='2026년5월전체'!C59 -> 오제국 | D24: ='2026년5월전체'!AS59 -> 10 | E24: ='2026년5월전체'!AV59 -> 0 | F24: ='2026년5월전체'!AW59 -> 0 | G24: ='2026년5월전체'!AX59 -> 0 | H24: ='2026년5월전체'!AY59 -> 0 | I24: ='2026년5월전체'!AZ59 -> 0 | K24: ='2026년5월전체'!BB59 -> 0 | L24: ='2026년5월전체'!BC59 -> 0 | M24: ='2026년5월전체'!BD59 -> 0 | N24: ='2026년5월전체'!BE59 -> 0 | O24: ='2026년5월전체'!BF59 -> 0 | P24: =SUM(K24:O24,K25:O25) -> 0
C25: ='2026년5월전체'!G59 -> 46146 | D25: ='2026년5월전체'!AU59 -> 180000 | E25: ='2026년5월전체'!AV60 -> 0 | F25: ='2026년5월전체'!AW60 -> 0 | G25: ='2026년5월전체'!AX60 -> 0 | H25: ='2026년5월전체'!AY60 -> 0 | I25: ='2026년5월전체'!AZ60 -> 0 | J25: =SUM(E24:I24,E25:I25) -> 0 | K25: ='2026년5월전체'!BB60 -> 0 | L25: ='2026년5월전체'!BC60 -> 0 | M25: ='2026년5월전체'!BD60 -> 0 | N25: ='2026년5월전체'!BE60 -> 0 | O25: ='2026년5월전체'!BF60 -> 0 | P25: =J25-P24 -> 0
B26: 11 | C26: ='2026년5월전체'!C62 -> 이미선 | D26: ='2026년5월전체'!AS62 -> 0 | E26: ='2026년5월전체'!AV62 -> 0 | F26: ='2026년5월전체'!AW62 -> 0 | G26: ='2026년5월전체'!AX62 -> 0 | H26: ='2026년5월전체'!AY62 -> 0 | I26: ='2026년5월전체'!AZ62 -> 0 | K26: ='2026년5월전체'!BB62 -> 0 | L26: ='2026년5월전체'!BC62 -> 0 | M26: ='2026년5월전체'!BD62 -> 0 | N26: ='2026년5월전체'!BE62 -> 0 | O26: ='2026년5월전체'!BF62 -> 0 | P26: =SUM(K26:O26,K27:O27) -> 0
C27: ='2026년5월전체'!G62 -> 0 | D27: ='2026년5월전체'!AU62 -> 200000 | E27: ='2026년5월전체'!AV63 -> 0 | F27: ='2026년5월전체'!AW63 -> 0 | G27: ='2026년5월전체'!AX63 -> 0 | H27: ='2026년5월전체'!AY63 -> 0 | I27: ='2026년5월전체'!AZ63 -> 0 | J27: =SUM(E26:I26,E27:I27) -> 0 | K27: ='2026년5월전체'!BB63 -> 0 | L27: ='2026년5월전체'!BC63 -> 0 | M27: ='2026년5월전체'!BD63 -> 0 | N27: ='2026년5월전체'!BE63 -> 0 | O27: ='2026년5월전체'!BF63 -> 0 | P27: =J27-P26 -> 0
B28: 12 | C28: ='2026년5월전체'!C65 -> 호반동 | D28: ='2026년5월전체'!AS65 -> 0 | E28: ='2026년5월전체'!AV65 -> 0 | F28: ='2026년5월전체'!AW65 -> 0 | G28: ='2026년5월전체'!AX65 -> 0 | H28: ='2026년5월전체'!AY65 -> 0 | I28: ='2026년5월전체'!AZ65 -> 0 | K28: ='2026년5월전체'!BB65 -> 0 | L28: ='2026년5월전체'!BC65 -> 0 | M28: ='2026년5월전체'!BD65 -> 0 | N28: ='2026년5월전체'!BE65 -> 0 | O28: ='2026년5월전체'!BF65 -> 0 | P28: =SUM(K28:O28,K29:O29) -> 0
C29: ='2026년5월전체'!G65 -> 0 | D29: ='2026년5월전체'!AU65 -> 130000 | E29: ='2026년5월전체'!AV66 -> 0 | F29: ='2026년5월전체'!AW66 -> 0 | G29: ='2026년5월전체'!AX66 -> 0 | H29: ='2026년5월전체'!AY66 -> 0 | I29: ='2026년5월전체'!AZ66 -> 0 | J29: =SUM(E28:I28,E29:I29) -> 0 | K29: ='2026년5월전체'!BB66 -> 0 | L29: ='2026년5월전체'!BC66 -> 0 | M29: ='2026년5월전체'!BD66 -> 0 | N29: ='2026년5월전체'!BE66 -> 0 | O29: ='2026년5월전체'!BF66 -> 0 | P29: =J29-P28 -> 0
B30: 계 | E30: =E6+E8+E10+E12+E14+E16+E18+E20+E22+E24+E26+E28 -> 0 | F30: =F6+F8+F10+F12+F14+F16+F18+F20+F22+F24+F26+F28 -> 0 | G30: =G6+G8+G10+G12+G14+G16+G18+G20+G22+G24+G26+G28 -> 0 | H30: =H6+H8+H10+H12+H14+H16+H18+H20+H22+H24+H26+H28 -> 0 | I30: =I6+I8+I10+I12+I14+I16+I18+I20+I22+I24+I26+I28 -> 0 | J30: =J6+J8+J10+J12+J14+J16+J18+J20+J22+J24+J26+J28 -> 0 | K30: =K6+K8+K10+K12+K14+K16+K18+K20+K22+K24+K26+K28 -> 0 | L30: =L6+L8+L10+L12+L14+L16+L18+L20+L22+L24+L26+L28 -> 0 | ... N30: =N6+N8+N10+N12+N14+N16+N18+N20+N22+N24+N26+N28 -> 0 | P30: =SUM(K30:O30,K31:O31) -> 0
E31: =E7+E9+E11+E13+E15+E17+E19+E21+E23+E25+E27+E29 -> 0 | F31: =F7+F9+F11+F13+F15+F17+F19+F21+F23+F25+F27+F29 -> 0 | G31: =G7+G9+G11+G13+G15+G17+G19+G21+G23+G25+G27+G29 -> 0 | H31: =H7+H9+H11+H13+H15+H17+H19+H21+H23+H25+H27+H29 -> 0 | I31: =I7+I9+I11+I13+I15+I17+I19+I21+I23+I25+I27+I29 -> 0 | J31: =J7+J9+J11+J13+J15+J17+J19+J21+J23+J25+J27+J29 -> 0 | K31: =K7+K9+K11+K13+K15+K17+K19+K21+K23+K25+K27+K29 -> 0 | L31: =L7+L9+L11+L13+L15+L17+L19+L21+L23+L25+L27+L29 -> 0 | ... N31: =N7+N9+N11+N13+N15+N17+N19+N21+N23+N25+N27+N29 -> 0 | P31: =J31-P30 -> 0

Sheet 급여정산 테이블
B2: 월급/시급 급여 정산 테이블
B3: 잔업 구분 | C3: 월급 | D3: 시급
B4: 연장 | C4: 1.5 | D4: 1.5
B5: 휴일 | C5: 1.5 | D5: 1.5
B6: 휴일연장 | C6: 2 | D6: 2
B7: 심야 | C7: 0.5 | D7: 0.5
B8: 점심시간
B10: 일용/사업소득 정산 테이블
B11: 구분 | C11: 시간 | E11: 일당
B12: 평일 | C12: 0.20833333 | D12: 0.33333333 | E12: 0.5
B13: 평일 | C13: 0.33333333 | D13: 0.70833333 | E13: 1
B14: 평일 | C14: 0.70833333 | D14: 0.8125 | E14: 0.5
B15: 토요일/공휴일 | C15: 0.20833333 | D15: 0.33333333 | E15: 0.5
B16: 토요일/공휴일 | C16: 0.33333333 | D16: 0.66666667 | E16: 1
B17: 토요일/공휴일 | C17: 0.66666667 | D17: 0.75 | E17: 0.5
B18: 일요일 | C18: 0.20833333 | D18: 0.33333333 | E18: 0.5
B19: 일요일 | C19: 0.33333333 | D19: 0.64583333 | E19: 1
B20: 일요일 | C20: 0.64583333 | D20: 0.72916667 | E20: 0.5
B21: 점심시간 | C21: 0.5 | D21: 0.54166667 | E21: 0

Sheet 급여명세서(월급,일용,시급)
B2: =TEXT(EDATE(DATE('2026년5월전체'!S1,'2026년5월전체'!V1,1),1),"yyyy년 m월")&" 급여명세서" -> 2026년 6월 급여명세서
B4: 사원코드 : | E4: ='2026년5월전체'!B26 -> CM009 | I4: 이 름 : | L4: ='2026년5월전체'!C26 -> 따이 | P4: 입 사 일 : | S4: ='2026년5월전체'!G26 -> 0
B5: 부 서 : | E5: ="생산부" -> 생산부 | I5: 직 급 : | L5: ="사원" -> 사원 | P5: 지 급 일 :
B6: 지 급 내 역 | M6: 공 제 내 역
B7: 내 역 | H7: 금 액 | M7: 내 역 | R7: 금 액
B8: 기본급 | H8: ='2026년5월전체'!AV26 -> 1956880 | M8: 국민연금 | R8: ='2026년5월전체'!BB26 -> 0
B9: 식 대 | H9: ='2026년5월전체'!AW26 -> 200000 | M9: 건강보험 | R9: ='2026년5월전체'!BC26 -> 0
B10: 자운전보조비 | H10: ='2026년5월전체'!AX26 -> 0 | M10: 장기요양보험 | R10: ='2026년5월전체'!BD26 -> 0
B11: 연장수당 | H11: ='2026년5월전체'!AV27 -> 0 | M11: 고용보험 | R11: ='2026년5월전체'!BB27 -> 0
B12: 휴일수당 | H12: ='2026년5월전체'!AW27 -> 0 | M12: 소 득 세 | R12: ='2026년5월전체'!BC27 -> 0
B13: 휴일연장수당 | H13: ='2026년5월전체'!AX27 -> 0 | M13: 지방소득세 | R13: ='2026년5월전체'!BD27 -> 0
B14: 심야수당 | H14: ='2026년5월전체'!AY27 -> 0 | M14: 숙소료 | R14: ='2026년5월전체'!BE26 -> 100000
B15: 직책수당 | H15: ='2026년5월전체'!AZ26 -> 0 | M15: 가 불 금 | R15: ='2026년5월전체'!BE27 -> 0
B16: 성과금 | H16: =0 -> 0 | M16: 기타 | R16: =SUM('2026년5월전체'!BF26,'2026년5월전체'!BF27) -> 0
B17: 기타 | H17: =SUM('2026년5월전체'!AY26,'2026년5월전체'!AZ27) -> 0
H19: =SUM(H8:H17) -> 2156880 | M19: 공제액계 | R19: =SUM(R8:R16) -> 100000
B20: 지급액계 | H20: =SUM(H8:L19) -> 4313760 | M20: 실지급액 | R20: =H19-R19 -> 2056880
B21: 예 금 주 : | E21: ='[1]1.설정'!B7 -> 0 | J21: 계좌번호 : | N21: ='[1]1.설정'!B8 -> 0
B22: 귀하의 노고에 감사드립니다.
B23: 씨엠(CM)건설

Sheet 급여명세서(사업소득자)
B2: =TEXT(DATE('2026년5월전체'!S1,'2026년5월전체'!V1,1),"yyyy년 m월")&" 사업소득명세서" -> 2026년 5월 사업소득명세서
B4: 사원코드 : | E4: ='2026년5월전체'!B32 -> CM011 | L4: ='2026년5월전체'!C32 -> 이학철 | P4: 계 약 일 : | S4: ='2026년5월전체'!G32 -> 0
B5: ="이 름 :" -> 이 름 : | I5: ="정산기간 :" -> 정산기간 : | L5: =TEXT(DATE('2026년5월전체'!S1,'2026년5월전체'!V1,1),"yy/m/d")&"~"&TEXT(EOMONTH(DATE('2026년5월전체'!S1,'2026년5월전체'!V1,1),0),"m/d") -> 26/5/1~5/31 | P5: 지 급 일 :
B6: 지 급 내 역 | M6: 공 제 내 역
B7: 내 역 | H7: 금 액 | M7: 내 역 | R7: 금 액
B8: 계약금액 | H8: =SUM('2026년5월전체'!AV32:AZ33) -> 0 | M8: 소득세 | R8: ='2026년5월전체'!BB33 -> 0
M9: 지방소득세 | R9: ='2026년5월전체'!BC33 -> 0
M10: 숙소료 | R10: ='2026년5월전체'!BE32 -> 0
M11: 가불 | R11: ='2026년5월전체'!BE33 -> 0
M12: 기타 | R12: =SUM(R8:R11) -> 0
B19: 상기 금액에는 주휴수당,연차수당 포함 | M19: 공제액계 | R19: =SUM(R8:W18) -> 0
B20: 지급액계 | H20: =H8 -> 0 | M20: 실지급액 | R20: =H20-R18 -> 0
B21: 예 금 주 : | E21: ='2026년5월전체'!C32 -> 이학철 | J21: 계좌번호 : | N21: ='2026년5월전체'!I32 -> 농협 351-0837-1428-13
B22: 귀하의 노고에 감사드립니다.
B23: 씨엠(CM)건설
